{
 "cells": [
  {
   "cell_type": "code",
   "execution_count": 1,
   "metadata": {},
   "outputs": [],
   "source": [
    "import pandas as pd\n",
    "from imdb import Cinemagoer\n",
    "from tools.imdb_multproc import *\n",
    "from tools.wikidata import *\n",
    "from tools.moviedb_multproc import *\n"
   ]
  },
  {
   "cell_type": "code",
   "execution_count": 2,
   "metadata": {},
   "outputs": [],
   "source": [
    "movies=pd.read_csv(\"dataset/movie.metadata.tsv\",sep=\"\\t\",names=[\"Wikipedia movie ID\",\n",
    "                                                                \"Freebase movie ID\",\n",
    "                                                                \"Movie name\",\n",
    "                                                                \"Movie release date\",\n",
    "                                                                \"Movie box office revenue\",\n",
    "                                                                \"Movie runtime\",\n",
    "                                                                \"Movie languages\",\n",
    "                                                                \"Movie countries\",\n",
    "                                                                \"Movie genres\"])"
   ]
  },
  {
   "cell_type": "code",
   "execution_count": 69,
   "metadata": {},
   "outputs": [
    {
     "name": "stderr",
     "output_type": "stream",
     "text": [
      "2023-11-16 16:45:21,227 CRITICAL [imdbpy] /Users/berkeargin/opt/anaconda3/lib/python3.9/site-packages/imdb/_exceptions.py:32: IMDbDataAccessError exception raised; args: ({'errcode': None, 'errmsg': 'None', 'url': 'https://www.imdb.com/find/?q=Agitator+%282001%29&s=tt', 'proxy': '', 'exception type': 'IOError', 'original exception': <HTTPError 500: 'Internal Server Error'>},); kwds: {}\n",
      "Traceback (most recent call last):\n",
      "  File \"/Users/berkeargin/opt/anaconda3/lib/python3.9/site-packages/imdb/parser/http/__init__.py\", line 233, in retrieve_unicode\n",
      "    response = uopener.open(url)\n",
      "  File \"/Users/berkeargin/opt/anaconda3/lib/python3.9/urllib/request.py\", line 523, in open\n",
      "    response = meth(req, response)\n",
      "  File \"/Users/berkeargin/opt/anaconda3/lib/python3.9/urllib/request.py\", line 632, in http_response\n",
      "    response = self.parent.error(\n",
      "  File \"/Users/berkeargin/opt/anaconda3/lib/python3.9/urllib/request.py\", line 561, in error\n",
      "    return self._call_chain(*args)\n",
      "  File \"/Users/berkeargin/opt/anaconda3/lib/python3.9/urllib/request.py\", line 494, in _call_chain\n",
      "    result = func(*args)\n",
      "  File \"/Users/berkeargin/opt/anaconda3/lib/python3.9/urllib/request.py\", line 641, in http_error_default\n",
      "    raise HTTPError(req.full_url, code, msg, hdrs, fp)\n",
      "urllib.error.HTTPError: HTTP Error 500: Internal Server Error\n",
      "2023-11-16 16:45:28,528 CRITICAL [imdbpy] /Users/berkeargin/opt/anaconda3/lib/python3.9/site-packages/imdb/_exceptions.py:32: IMDbDataAccessError exception raised; args: ({'errcode': None, 'errmsg': 'None', 'url': 'https://www.imdb.com/find/?q=Der+wei%C3%9Fblaue+L%C3%B6we+%281952%29&s=tt', 'proxy': '', 'exception type': 'IOError', 'original exception': <HTTPError 500: 'Internal Server Error'>},); kwds: {}\n",
      "Traceback (most recent call last):\n",
      "  File \"/Users/berkeargin/opt/anaconda3/lib/python3.9/site-packages/imdb/parser/http/__init__.py\", line 233, in retrieve_unicode\n",
      "    response = uopener.open(url)\n",
      "  File \"/Users/berkeargin/opt/anaconda3/lib/python3.9/urllib/request.py\", line 523, in open\n",
      "    response = meth(req, response)\n",
      "  File \"/Users/berkeargin/opt/anaconda3/lib/python3.9/urllib/request.py\", line 632, in http_response\n",
      "    response = self.parent.error(\n",
      "  File \"/Users/berkeargin/opt/anaconda3/lib/python3.9/urllib/request.py\", line 561, in error\n",
      "    return self._call_chain(*args)\n",
      "  File \"/Users/berkeargin/opt/anaconda3/lib/python3.9/urllib/request.py\", line 494, in _call_chain\n",
      "    result = func(*args)\n",
      "  File \"/Users/berkeargin/opt/anaconda3/lib/python3.9/urllib/request.py\", line 641, in http_error_default\n",
      "    raise HTTPError(req.full_url, code, msg, hdrs, fp)\n",
      "urllib.error.HTTPError: HTTP Error 500: Internal Server Error\n",
      "2023-11-16 16:45:46,214 CRITICAL [imdbpy] /Users/berkeargin/opt/anaconda3/lib/python3.9/site-packages/imdb/_exceptions.py:32: IMDbDataAccessError exception raised; args: ({'errcode': None, 'errmsg': 'None', 'url': 'https://www.imdb.com/find/?q=Signs+%26+Wonders+%282000%29&s=tt', 'proxy': '', 'exception type': 'IOError', 'original exception': <HTTPError 500: 'Internal Server Error'>},); kwds: {}\n",
      "Traceback (most recent call last):\n",
      "  File \"/Users/berkeargin/opt/anaconda3/lib/python3.9/site-packages/imdb/parser/http/__init__.py\", line 233, in retrieve_unicode\n",
      "    response = uopener.open(url)\n",
      "  File \"/Users/berkeargin/opt/anaconda3/lib/python3.9/urllib/request.py\", line 523, in open\n",
      "    response = meth(req, response)\n",
      "  File \"/Users/berkeargin/opt/anaconda3/lib/python3.9/urllib/request.py\", line 632, in http_response\n",
      "    response = self.parent.error(\n",
      "  File \"/Users/berkeargin/opt/anaconda3/lib/python3.9/urllib/request.py\", line 561, in error\n",
      "    return self._call_chain(*args)\n",
      "  File \"/Users/berkeargin/opt/anaconda3/lib/python3.9/urllib/request.py\", line 494, in _call_chain\n",
      "    result = func(*args)\n",
      "  File \"/Users/berkeargin/opt/anaconda3/lib/python3.9/urllib/request.py\", line 641, in http_error_default\n",
      "    raise HTTPError(req.full_url, code, msg, hdrs, fp)\n",
      "urllib.error.HTTPError: HTTP Error 500: Internal Server Error\n",
      "2023-11-16 16:45:58,682 CRITICAL [imdbpy] /Users/berkeargin/opt/anaconda3/lib/python3.9/site-packages/imdb/_exceptions.py:32: IMDbDataAccessError exception raised; args: ({'errcode': None, 'errmsg': 'None', 'url': 'https://www.imdb.com/find/?q=Golden+Dawn+%281930%29&s=tt', 'proxy': '', 'exception type': 'IOError', 'original exception': <HTTPError 500: 'Internal Server Error'>},); kwds: {}\n",
      "Traceback (most recent call last):\n",
      "  File \"/Users/berkeargin/opt/anaconda3/lib/python3.9/site-packages/imdb/parser/http/__init__.py\", line 233, in retrieve_unicode\n",
      "    response = uopener.open(url)\n",
      "  File \"/Users/berkeargin/opt/anaconda3/lib/python3.9/urllib/request.py\", line 523, in open\n",
      "    response = meth(req, response)\n",
      "  File \"/Users/berkeargin/opt/anaconda3/lib/python3.9/urllib/request.py\", line 632, in http_response\n",
      "    response = self.parent.error(\n",
      "  File \"/Users/berkeargin/opt/anaconda3/lib/python3.9/urllib/request.py\", line 561, in error\n",
      "    return self._call_chain(*args)\n",
      "  File \"/Users/berkeargin/opt/anaconda3/lib/python3.9/urllib/request.py\", line 494, in _call_chain\n",
      "    result = func(*args)\n",
      "  File \"/Users/berkeargin/opt/anaconda3/lib/python3.9/urllib/request.py\", line 641, in http_error_default\n",
      "    raise HTTPError(req.full_url, code, msg, hdrs, fp)\n",
      "urllib.error.HTTPError: HTTP Error 500: Internal Server Error\n",
      "2023-11-16 16:46:09,272 CRITICAL [imdbpy] /Users/berkeargin/opt/anaconda3/lib/python3.9/site-packages/imdb/_exceptions.py:32: IMDbDataAccessError exception raised; args: ({'errcode': None, 'errmsg': 'None', 'url': 'https://www.imdb.com/find/?q=The+Return+%282003%29&s=tt', 'proxy': '', 'exception type': 'IOError', 'original exception': <HTTPError 405: 'Not Allowed'>},); kwds: {}\n",
      "Traceback (most recent call last):\n",
      "  File \"/Users/berkeargin/opt/anaconda3/lib/python3.9/site-packages/imdb/parser/http/__init__.py\", line 233, in retrieve_unicode\n",
      "    response = uopener.open(url)\n",
      "  File \"/Users/berkeargin/opt/anaconda3/lib/python3.9/urllib/request.py\", line 523, in open\n",
      "    response = meth(req, response)\n",
      "  File \"/Users/berkeargin/opt/anaconda3/lib/python3.9/urllib/request.py\", line 632, in http_response\n",
      "    response = self.parent.error(\n",
      "  File \"/Users/berkeargin/opt/anaconda3/lib/python3.9/urllib/request.py\", line 561, in error\n",
      "    return self._call_chain(*args)\n",
      "  File \"/Users/berkeargin/opt/anaconda3/lib/python3.9/urllib/request.py\", line 494, in _call_chain\n",
      "    result = func(*args)\n",
      "  File \"/Users/berkeargin/opt/anaconda3/lib/python3.9/urllib/request.py\", line 641, in http_error_default\n",
      "    raise HTTPError(req.full_url, code, msg, hdrs, fp)\n",
      "urllib.error.HTTPError: HTTP Error 405: Not Allowed\n",
      "2023-11-16 16:46:20,932 CRITICAL [imdbpy] /Users/berkeargin/opt/anaconda3/lib/python3.9/site-packages/imdb/_exceptions.py:32: IMDbDataAccessError exception raised; args: ({'errcode': None, 'errmsg': 'None', 'url': 'https://www.imdb.com/find/?q=They+Wait+%282007%29&s=tt', 'proxy': '', 'exception type': 'IOError', 'original exception': <HTTPError 405: 'Not Allowed'>},); kwds: {}\n",
      "Traceback (most recent call last):\n",
      "  File \"/Users/berkeargin/opt/anaconda3/lib/python3.9/site-packages/imdb/parser/http/__init__.py\", line 233, in retrieve_unicode\n",
      "    response = uopener.open(url)\n",
      "  File \"/Users/berkeargin/opt/anaconda3/lib/python3.9/urllib/request.py\", line 523, in open\n",
      "    response = meth(req, response)\n",
      "  File \"/Users/berkeargin/opt/anaconda3/lib/python3.9/urllib/request.py\", line 632, in http_response\n",
      "    response = self.parent.error(\n",
      "  File \"/Users/berkeargin/opt/anaconda3/lib/python3.9/urllib/request.py\", line 561, in error\n",
      "    return self._call_chain(*args)\n",
      "  File \"/Users/berkeargin/opt/anaconda3/lib/python3.9/urllib/request.py\", line 494, in _call_chain\n",
      "    result = func(*args)\n",
      "  File \"/Users/berkeargin/opt/anaconda3/lib/python3.9/urllib/request.py\", line 641, in http_error_default\n",
      "    raise HTTPError(req.full_url, code, msg, hdrs, fp)\n",
      "urllib.error.HTTPError: HTTP Error 405: Not Allowed\n",
      "2023-11-16 16:46:43,018 CRITICAL [imdbpy] /Users/berkeargin/opt/anaconda3/lib/python3.9/site-packages/imdb/_exceptions.py:32: IMDbDataAccessError exception raised; args: ({'errcode': None, 'errmsg': 'None', 'url': 'https://www.imdb.com/find/?q=Breaking+Point+%281976%29&s=tt', 'proxy': '', 'exception type': 'IOError', 'original exception': <HTTPError 405: 'Not Allowed'>},); kwds: {}\n",
      "Traceback (most recent call last):\n",
      "  File \"/Users/berkeargin/opt/anaconda3/lib/python3.9/site-packages/imdb/parser/http/__init__.py\", line 233, in retrieve_unicode\n",
      "    response = uopener.open(url)\n",
      "  File \"/Users/berkeargin/opt/anaconda3/lib/python3.9/urllib/request.py\", line 523, in open\n",
      "    response = meth(req, response)\n",
      "  File \"/Users/berkeargin/opt/anaconda3/lib/python3.9/urllib/request.py\", line 632, in http_response\n",
      "    response = self.parent.error(\n",
      "  File \"/Users/berkeargin/opt/anaconda3/lib/python3.9/urllib/request.py\", line 561, in error\n",
      "    return self._call_chain(*args)\n",
      "  File \"/Users/berkeargin/opt/anaconda3/lib/python3.9/urllib/request.py\", line 494, in _call_chain\n",
      "    result = func(*args)\n",
      "  File \"/Users/berkeargin/opt/anaconda3/lib/python3.9/urllib/request.py\", line 641, in http_error_default\n",
      "    raise HTTPError(req.full_url, code, msg, hdrs, fp)\n",
      "urllib.error.HTTPError: HTTP Error 405: Not Allowed\n",
      "2023-11-16 16:47:10,756 CRITICAL [imdbpy] /Users/berkeargin/opt/anaconda3/lib/python3.9/site-packages/imdb/_exceptions.py:32: IMDbDataAccessError exception raised; args: ({'errcode': None, 'errmsg': 'None', 'url': 'https://www.imdb.com/find/?q=Sin+%281915%29&s=tt', 'proxy': '', 'exception type': 'IOError', 'original exception': <HTTPError 405: 'Not Allowed'>},); kwds: {}\n",
      "Traceback (most recent call last):\n",
      "  File \"/Users/berkeargin/opt/anaconda3/lib/python3.9/site-packages/imdb/parser/http/__init__.py\", line 233, in retrieve_unicode\n",
      "    response = uopener.open(url)\n",
      "  File \"/Users/berkeargin/opt/anaconda3/lib/python3.9/urllib/request.py\", line 523, in open\n",
      "    response = meth(req, response)\n",
      "  File \"/Users/berkeargin/opt/anaconda3/lib/python3.9/urllib/request.py\", line 632, in http_response\n",
      "    response = self.parent.error(\n",
      "  File \"/Users/berkeargin/opt/anaconda3/lib/python3.9/urllib/request.py\", line 561, in error\n",
      "    return self._call_chain(*args)\n",
      "  File \"/Users/berkeargin/opt/anaconda3/lib/python3.9/urllib/request.py\", line 494, in _call_chain\n",
      "    result = func(*args)\n",
      "  File \"/Users/berkeargin/opt/anaconda3/lib/python3.9/urllib/request.py\", line 641, in http_error_default\n",
      "    raise HTTPError(req.full_url, code, msg, hdrs, fp)\n",
      "urllib.error.HTTPError: HTTP Error 405: Not Allowed\n",
      "2023-11-16 16:47:38,231 CRITICAL [imdbpy] /Users/berkeargin/opt/anaconda3/lib/python3.9/site-packages/imdb/_exceptions.py:32: IMDbDataAccessError exception raised; args: ({'errcode': None, 'errmsg': 'None', 'url': 'https://www.imdb.com/find/?q=Hare+Trigger+%281945%29&s=tt', 'proxy': '', 'exception type': 'IOError', 'original exception': <HTTPError 405: 'Not Allowed'>},); kwds: {}\n",
      "Traceback (most recent call last):\n",
      "  File \"/Users/berkeargin/opt/anaconda3/lib/python3.9/site-packages/imdb/parser/http/__init__.py\", line 233, in retrieve_unicode\n",
      "    response = uopener.open(url)\n",
      "  File \"/Users/berkeargin/opt/anaconda3/lib/python3.9/urllib/request.py\", line 523, in open\n",
      "    response = meth(req, response)\n",
      "  File \"/Users/berkeargin/opt/anaconda3/lib/python3.9/urllib/request.py\", line 632, in http_response\n",
      "    response = self.parent.error(\n",
      "  File \"/Users/berkeargin/opt/anaconda3/lib/python3.9/urllib/request.py\", line 561, in error\n",
      "    return self._call_chain(*args)\n",
      "  File \"/Users/berkeargin/opt/anaconda3/lib/python3.9/urllib/request.py\", line 494, in _call_chain\n",
      "    result = func(*args)\n",
      "  File \"/Users/berkeargin/opt/anaconda3/lib/python3.9/urllib/request.py\", line 641, in http_error_default\n",
      "    raise HTTPError(req.full_url, code, msg, hdrs, fp)\n",
      "urllib.error.HTTPError: HTTP Error 405: Not Allowed\n",
      "2023-11-16 16:47:47,105 CRITICAL [imdbpy] /Users/berkeargin/opt/anaconda3/lib/python3.9/site-packages/imdb/_exceptions.py:32: IMDbDataAccessError exception raised; args: ({'errcode': None, 'errmsg': 'None', 'url': 'https://www.imdb.com/find/?q=Shake%2C+Rattle+and+Rock%21+%281994%29&s=tt', 'proxy': '', 'exception type': 'IOError', 'original exception': <HTTPError 405: 'Not Allowed'>},); kwds: {}\n",
      "Traceback (most recent call last):\n",
      "  File \"/Users/berkeargin/opt/anaconda3/lib/python3.9/site-packages/imdb/parser/http/__init__.py\", line 233, in retrieve_unicode\n",
      "    response = uopener.open(url)\n",
      "  File \"/Users/berkeargin/opt/anaconda3/lib/python3.9/urllib/request.py\", line 523, in open\n",
      "    response = meth(req, response)\n",
      "  File \"/Users/berkeargin/opt/anaconda3/lib/python3.9/urllib/request.py\", line 632, in http_response\n",
      "    response = self.parent.error(\n",
      "  File \"/Users/berkeargin/opt/anaconda3/lib/python3.9/urllib/request.py\", line 561, in error\n",
      "    return self._call_chain(*args)\n",
      "  File \"/Users/berkeargin/opt/anaconda3/lib/python3.9/urllib/request.py\", line 494, in _call_chain\n",
      "    result = func(*args)\n",
      "  File \"/Users/berkeargin/opt/anaconda3/lib/python3.9/urllib/request.py\", line 641, in http_error_default\n",
      "    raise HTTPError(req.full_url, code, msg, hdrs, fp)\n",
      "urllib.error.HTTPError: HTTP Error 405: Not Allowed\n",
      "2023-11-16 16:47:52,170 CRITICAL [imdbpy] /Users/berkeargin/opt/anaconda3/lib/python3.9/site-packages/imdb/_exceptions.py:32: IMDbDataAccessError exception raised; args: ({'errcode': None, 'errmsg': 'None', 'url': 'https://www.imdb.com/find/?q=Groundhog+Day+%281993%29&s=tt', 'proxy': '', 'exception type': 'IOError', 'original exception': <HTTPError 405: 'Not Allowed'>},); kwds: {}\n",
      "Traceback (most recent call last):\n",
      "  File \"/Users/berkeargin/opt/anaconda3/lib/python3.9/site-packages/imdb/parser/http/__init__.py\", line 233, in retrieve_unicode\n",
      "    response = uopener.open(url)\n",
      "  File \"/Users/berkeargin/opt/anaconda3/lib/python3.9/urllib/request.py\", line 523, in open\n",
      "    response = meth(req, response)\n",
      "  File \"/Users/berkeargin/opt/anaconda3/lib/python3.9/urllib/request.py\", line 632, in http_response\n",
      "    response = self.parent.error(\n",
      "  File \"/Users/berkeargin/opt/anaconda3/lib/python3.9/urllib/request.py\", line 561, in error\n",
      "    return self._call_chain(*args)\n",
      "  File \"/Users/berkeargin/opt/anaconda3/lib/python3.9/urllib/request.py\", line 494, in _call_chain\n",
      "    result = func(*args)\n",
      "  File \"/Users/berkeargin/opt/anaconda3/lib/python3.9/urllib/request.py\", line 641, in http_error_default\n",
      "    raise HTTPError(req.full_url, code, msg, hdrs, fp)\n",
      "urllib.error.HTTPError: HTTP Error 405: Not Allowed\n",
      "2023-11-16 16:48:11,197 CRITICAL [imdbpy] /Users/berkeargin/opt/anaconda3/lib/python3.9/site-packages/imdb/_exceptions.py:32: IMDbDataAccessError exception raised; args: ({'errcode': None, 'errmsg': 'None', 'url': 'https://www.imdb.com/find/?q=Ice+Age+%281975%29&s=tt', 'proxy': '', 'exception type': 'IOError', 'original exception': <HTTPError 405: 'Not Allowed'>},); kwds: {}\n",
      "Traceback (most recent call last):\n",
      "  File \"/Users/berkeargin/opt/anaconda3/lib/python3.9/site-packages/imdb/parser/http/__init__.py\", line 233, in retrieve_unicode\n",
      "    response = uopener.open(url)\n",
      "  File \"/Users/berkeargin/opt/anaconda3/lib/python3.9/urllib/request.py\", line 523, in open\n",
      "    response = meth(req, response)\n",
      "  File \"/Users/berkeargin/opt/anaconda3/lib/python3.9/urllib/request.py\", line 632, in http_response\n",
      "    response = self.parent.error(\n",
      "  File \"/Users/berkeargin/opt/anaconda3/lib/python3.9/urllib/request.py\", line 561, in error\n",
      "    return self._call_chain(*args)\n",
      "  File \"/Users/berkeargin/opt/anaconda3/lib/python3.9/urllib/request.py\", line 494, in _call_chain\n",
      "    result = func(*args)\n",
      "  File \"/Users/berkeargin/opt/anaconda3/lib/python3.9/urllib/request.py\", line 641, in http_error_default\n",
      "    raise HTTPError(req.full_url, code, msg, hdrs, fp)\n",
      "urllib.error.HTTPError: HTTP Error 405: Not Allowed\n",
      "2023-11-16 16:49:23,974 CRITICAL [imdbpy] /Users/berkeargin/opt/anaconda3/lib/python3.9/site-packages/imdb/_exceptions.py:32: IMDbDataAccessError exception raised; args: ({'errcode': None, 'errmsg': 'None', 'url': 'https://www.imdb.com/find/?q=Roarin%27+Lead+%281936%29&s=tt', 'proxy': '', 'exception type': 'IOError', 'original exception': <HTTPError 405: 'Not Allowed'>},); kwds: {}\n",
      "Traceback (most recent call last):\n",
      "  File \"/Users/berkeargin/opt/anaconda3/lib/python3.9/site-packages/imdb/parser/http/__init__.py\", line 233, in retrieve_unicode\n",
      "    response = uopener.open(url)\n",
      "  File \"/Users/berkeargin/opt/anaconda3/lib/python3.9/urllib/request.py\", line 523, in open\n",
      "    response = meth(req, response)\n",
      "  File \"/Users/berkeargin/opt/anaconda3/lib/python3.9/urllib/request.py\", line 632, in http_response\n",
      "    response = self.parent.error(\n",
      "  File \"/Users/berkeargin/opt/anaconda3/lib/python3.9/urllib/request.py\", line 561, in error\n",
      "    return self._call_chain(*args)\n",
      "  File \"/Users/berkeargin/opt/anaconda3/lib/python3.9/urllib/request.py\", line 494, in _call_chain\n",
      "    result = func(*args)\n",
      "  File \"/Users/berkeargin/opt/anaconda3/lib/python3.9/urllib/request.py\", line 641, in http_error_default\n",
      "    raise HTTPError(req.full_url, code, msg, hdrs, fp)\n",
      "urllib.error.HTTPError: HTTP Error 405: Not Allowed\n",
      "2023-11-16 16:50:06,804 CRITICAL [imdbpy] /Users/berkeargin/opt/anaconda3/lib/python3.9/site-packages/imdb/_exceptions.py:32: IMDbDataAccessError exception raised; args: ({'errcode': None, 'errmsg': 'None', 'url': 'https://www.imdb.com/find/?q=The+Return+of+the+Sister+Street+Fighter+%281975%29&s=tt', 'proxy': '', 'exception type': 'IOError', 'original exception': <HTTPError 500: 'Internal Server Error'>},); kwds: {}\n",
      "Traceback (most recent call last):\n",
      "  File \"/Users/berkeargin/opt/anaconda3/lib/python3.9/site-packages/imdb/parser/http/__init__.py\", line 233, in retrieve_unicode\n",
      "    response = uopener.open(url)\n",
      "  File \"/Users/berkeargin/opt/anaconda3/lib/python3.9/urllib/request.py\", line 523, in open\n",
      "    response = meth(req, response)\n",
      "  File \"/Users/berkeargin/opt/anaconda3/lib/python3.9/urllib/request.py\", line 632, in http_response\n",
      "    response = self.parent.error(\n",
      "  File \"/Users/berkeargin/opt/anaconda3/lib/python3.9/urllib/request.py\", line 561, in error\n",
      "    return self._call_chain(*args)\n",
      "  File \"/Users/berkeargin/opt/anaconda3/lib/python3.9/urllib/request.py\", line 494, in _call_chain\n",
      "    result = func(*args)\n",
      "  File \"/Users/berkeargin/opt/anaconda3/lib/python3.9/urllib/request.py\", line 641, in http_error_default\n",
      "    raise HTTPError(req.full_url, code, msg, hdrs, fp)\n",
      "urllib.error.HTTPError: HTTP Error 500: Internal Server Error\n",
      "2023-11-16 16:50:53,112 CRITICAL [imdbpy] /Users/berkeargin/opt/anaconda3/lib/python3.9/site-packages/imdb/_exceptions.py:32: IMDbDataAccessError exception raised; args: ({'errcode': None, 'errmsg': 'None', 'url': 'https://www.imdb.com/find/?q=Big+Time+%281988%29&s=tt', 'proxy': '', 'exception type': 'IOError', 'original exception': <HTTPError 405: 'Not Allowed'>},); kwds: {}\n",
      "Traceback (most recent call last):\n",
      "  File \"/Users/berkeargin/opt/anaconda3/lib/python3.9/site-packages/imdb/parser/http/__init__.py\", line 233, in retrieve_unicode\n",
      "    response = uopener.open(url)\n",
      "  File \"/Users/berkeargin/opt/anaconda3/lib/python3.9/urllib/request.py\", line 523, in open\n",
      "    response = meth(req, response)\n",
      "  File \"/Users/berkeargin/opt/anaconda3/lib/python3.9/urllib/request.py\", line 632, in http_response\n",
      "    response = self.parent.error(\n",
      "  File \"/Users/berkeargin/opt/anaconda3/lib/python3.9/urllib/request.py\", line 561, in error\n",
      "    return self._call_chain(*args)\n",
      "  File \"/Users/berkeargin/opt/anaconda3/lib/python3.9/urllib/request.py\", line 494, in _call_chain\n",
      "    result = func(*args)\n",
      "  File \"/Users/berkeargin/opt/anaconda3/lib/python3.9/urllib/request.py\", line 641, in http_error_default\n",
      "    raise HTTPError(req.full_url, code, msg, hdrs, fp)\n",
      "urllib.error.HTTPError: HTTP Error 405: Not Allowed\n",
      "2023-11-16 16:50:57,342 CRITICAL [imdbpy] /Users/berkeargin/opt/anaconda3/lib/python3.9/site-packages/imdb/_exceptions.py:32: IMDbDataAccessError exception raised; args: ({'errcode': None, 'errmsg': 'None', 'url': 'https://www.imdb.com/find/?q=Deep+Space+%281988%29&s=tt', 'proxy': '', 'exception type': 'IOError', 'original exception': <HTTPError 405: 'Not Allowed'>},); kwds: {}\n",
      "Traceback (most recent call last):\n",
      "  File \"/Users/berkeargin/opt/anaconda3/lib/python3.9/site-packages/imdb/parser/http/__init__.py\", line 233, in retrieve_unicode\n",
      "    response = uopener.open(url)\n",
      "  File \"/Users/berkeargin/opt/anaconda3/lib/python3.9/urllib/request.py\", line 523, in open\n",
      "    response = meth(req, response)\n",
      "  File \"/Users/berkeargin/opt/anaconda3/lib/python3.9/urllib/request.py\", line 632, in http_response\n",
      "    response = self.parent.error(\n",
      "  File \"/Users/berkeargin/opt/anaconda3/lib/python3.9/urllib/request.py\", line 561, in error\n",
      "    return self._call_chain(*args)\n",
      "  File \"/Users/berkeargin/opt/anaconda3/lib/python3.9/urllib/request.py\", line 494, in _call_chain\n",
      "    result = func(*args)\n",
      "  File \"/Users/berkeargin/opt/anaconda3/lib/python3.9/urllib/request.py\", line 641, in http_error_default\n",
      "    raise HTTPError(req.full_url, code, msg, hdrs, fp)\n",
      "urllib.error.HTTPError: HTTP Error 405: Not Allowed\n",
      "2023-11-16 16:50:59,637 CRITICAL [imdbpy] /Users/berkeargin/opt/anaconda3/lib/python3.9/site-packages/imdb/_exceptions.py:32: IMDbDataAccessError exception raised; args: ({'errcode': None, 'errmsg': 'None', 'url': 'https://www.imdb.com/find/?q=The+Whole+Shootin%27+Match+%281978%29&s=tt', 'proxy': '', 'exception type': 'IOError', 'original exception': <HTTPError 405: 'Not Allowed'>},); kwds: {}\n",
      "Traceback (most recent call last):\n",
      "  File \"/Users/berkeargin/opt/anaconda3/lib/python3.9/site-packages/imdb/parser/http/__init__.py\", line 233, in retrieve_unicode\n",
      "    response = uopener.open(url)\n",
      "  File \"/Users/berkeargin/opt/anaconda3/lib/python3.9/urllib/request.py\", line 523, in open\n",
      "    response = meth(req, response)\n",
      "  File \"/Users/berkeargin/opt/anaconda3/lib/python3.9/urllib/request.py\", line 632, in http_response\n",
      "    response = self.parent.error(\n",
      "  File \"/Users/berkeargin/opt/anaconda3/lib/python3.9/urllib/request.py\", line 561, in error\n",
      "    return self._call_chain(*args)\n",
      "  File \"/Users/berkeargin/opt/anaconda3/lib/python3.9/urllib/request.py\", line 494, in _call_chain\n",
      "    result = func(*args)\n",
      "  File \"/Users/berkeargin/opt/anaconda3/lib/python3.9/urllib/request.py\", line 641, in http_error_default\n",
      "    raise HTTPError(req.full_url, code, msg, hdrs, fp)\n",
      "urllib.error.HTTPError: HTTP Error 405: Not Allowed\n",
      "2023-11-16 16:51:01,145 CRITICAL [imdbpy] /Users/berkeargin/opt/anaconda3/lib/python3.9/site-packages/imdb/_exceptions.py:32: IMDbDataAccessError exception raised; args: ({'errcode': None, 'errmsg': 'None', 'url': 'https://www.imdb.com/find/?q=Trigger+%282010%29&s=tt', 'proxy': '', 'exception type': 'IOError', 'original exception': <HTTPError 405: 'Not Allowed'>},); kwds: {}\n",
      "Traceback (most recent call last):\n",
      "  File \"/Users/berkeargin/opt/anaconda3/lib/python3.9/site-packages/imdb/parser/http/__init__.py\", line 233, in retrieve_unicode\n",
      "    response = uopener.open(url)\n",
      "  File \"/Users/berkeargin/opt/anaconda3/lib/python3.9/urllib/request.py\", line 523, in open\n",
      "    response = meth(req, response)\n",
      "  File \"/Users/berkeargin/opt/anaconda3/lib/python3.9/urllib/request.py\", line 632, in http_response\n",
      "    response = self.parent.error(\n",
      "  File \"/Users/berkeargin/opt/anaconda3/lib/python3.9/urllib/request.py\", line 561, in error\n",
      "    return self._call_chain(*args)\n",
      "  File \"/Users/berkeargin/opt/anaconda3/lib/python3.9/urllib/request.py\", line 494, in _call_chain\n",
      "    result = func(*args)\n",
      "  File \"/Users/berkeargin/opt/anaconda3/lib/python3.9/urllib/request.py\", line 641, in http_error_default\n",
      "    raise HTTPError(req.full_url, code, msg, hdrs, fp)\n",
      "urllib.error.HTTPError: HTTP Error 405: Not Allowed\n",
      "2023-11-16 16:51:01,288 CRITICAL [imdbpy] /Users/berkeargin/opt/anaconda3/lib/python3.9/site-packages/imdb/_exceptions.py:32: IMDbDataAccessError exception raised; args: ({'errcode': None, 'errmsg': 'None', 'url': 'https://www.imdb.com/find/?q=To+%281964%29&s=tt', 'proxy': '', 'exception type': 'IOError', 'original exception': <HTTPError 405: 'Not Allowed'>},); kwds: {}\n",
      "Traceback (most recent call last):\n",
      "  File \"/Users/berkeargin/opt/anaconda3/lib/python3.9/site-packages/imdb/parser/http/__init__.py\", line 233, in retrieve_unicode\n",
      "    response = uopener.open(url)\n",
      "  File \"/Users/berkeargin/opt/anaconda3/lib/python3.9/urllib/request.py\", line 523, in open\n",
      "    response = meth(req, response)\n",
      "  File \"/Users/berkeargin/opt/anaconda3/lib/python3.9/urllib/request.py\", line 632, in http_response\n",
      "    response = self.parent.error(\n",
      "  File \"/Users/berkeargin/opt/anaconda3/lib/python3.9/urllib/request.py\", line 561, in error\n",
      "    return self._call_chain(*args)\n",
      "  File \"/Users/berkeargin/opt/anaconda3/lib/python3.9/urllib/request.py\", line 494, in _call_chain\n",
      "    result = func(*args)\n",
      "  File \"/Users/berkeargin/opt/anaconda3/lib/python3.9/urllib/request.py\", line 641, in http_error_default\n",
      "    raise HTTPError(req.full_url, code, msg, hdrs, fp)\n",
      "urllib.error.HTTPError: HTTP Error 405: Not Allowed\n",
      "2023-11-16 16:51:02,353 CRITICAL [imdbpy] /Users/berkeargin/opt/anaconda3/lib/python3.9/site-packages/imdb/_exceptions.py:32: IMDbDataAccessError exception raised; args: ({'errcode': None, 'errmsg': 'None', 'url': 'https://www.imdb.com/find/?q=Full+Circle+%281996%29&s=tt', 'proxy': '', 'exception type': 'IOError', 'original exception': <HTTPError 405: 'Not Allowed'>},); kwds: {}\n",
      "Traceback (most recent call last):\n",
      "  File \"/Users/berkeargin/opt/anaconda3/lib/python3.9/site-packages/imdb/parser/http/__init__.py\", line 233, in retrieve_unicode\n",
      "    response = uopener.open(url)\n",
      "  File \"/Users/berkeargin/opt/anaconda3/lib/python3.9/urllib/request.py\", line 523, in open\n",
      "    response = meth(req, response)\n",
      "  File \"/Users/berkeargin/opt/anaconda3/lib/python3.9/urllib/request.py\", line 632, in http_response\n",
      "    response = self.parent.error(\n",
      "  File \"/Users/berkeargin/opt/anaconda3/lib/python3.9/urllib/request.py\", line 561, in error\n",
      "    return self._call_chain(*args)\n",
      "  File \"/Users/berkeargin/opt/anaconda3/lib/python3.9/urllib/request.py\", line 494, in _call_chain\n",
      "    result = func(*args)\n",
      "  File \"/Users/berkeargin/opt/anaconda3/lib/python3.9/urllib/request.py\", line 641, in http_error_default\n",
      "    raise HTTPError(req.full_url, code, msg, hdrs, fp)\n",
      "urllib.error.HTTPError: HTTP Error 405: Not Allowed\n",
      "2023-11-16 16:51:02,768 CRITICAL [imdbpy] /Users/berkeargin/opt/anaconda3/lib/python3.9/site-packages/imdb/_exceptions.py:32: IMDbDataAccessError exception raised; args: ({'errcode': None, 'errmsg': 'None', 'url': 'https://www.imdb.com/find/?q=Nick+Name+and+The+Normals+%28nan%29&s=tt', 'proxy': '', 'exception type': 'IOError', 'original exception': <HTTPError 500: 'Internal Server Error'>},); kwds: {}\n",
      "Traceback (most recent call last):\n",
      "  File \"/Users/berkeargin/opt/anaconda3/lib/python3.9/site-packages/imdb/parser/http/__init__.py\", line 233, in retrieve_unicode\n",
      "    response = uopener.open(url)\n",
      "  File \"/Users/berkeargin/opt/anaconda3/lib/python3.9/urllib/request.py\", line 523, in open\n",
      "    response = meth(req, response)\n",
      "  File \"/Users/berkeargin/opt/anaconda3/lib/python3.9/urllib/request.py\", line 632, in http_response\n",
      "    response = self.parent.error(\n",
      "  File \"/Users/berkeargin/opt/anaconda3/lib/python3.9/urllib/request.py\", line 561, in error\n",
      "    return self._call_chain(*args)\n",
      "  File \"/Users/berkeargin/opt/anaconda3/lib/python3.9/urllib/request.py\", line 494, in _call_chain\n",
      "    result = func(*args)\n",
      "  File \"/Users/berkeargin/opt/anaconda3/lib/python3.9/urllib/request.py\", line 641, in http_error_default\n",
      "    raise HTTPError(req.full_url, code, msg, hdrs, fp)\n",
      "urllib.error.HTTPError: HTTP Error 500: Internal Server Error\n",
      "2023-11-16 16:51:05,466 CRITICAL [imdbpy] /Users/berkeargin/opt/anaconda3/lib/python3.9/site-packages/imdb/_exceptions.py:32: IMDbDataAccessError exception raised; args: ({'errcode': None, 'errmsg': 'None', 'url': 'https://www.imdb.com/find/?q=Man%2C+Woman+and+Sin+%281927%29&s=tt', 'proxy': '', 'exception type': 'IOError', 'original exception': <HTTPError 405: 'Not Allowed'>},); kwds: {}\n",
      "Traceback (most recent call last):\n",
      "  File \"/Users/berkeargin/opt/anaconda3/lib/python3.9/site-packages/imdb/parser/http/__init__.py\", line 233, in retrieve_unicode\n",
      "    response = uopener.open(url)\n",
      "  File \"/Users/berkeargin/opt/anaconda3/lib/python3.9/urllib/request.py\", line 523, in open\n",
      "    response = meth(req, response)\n",
      "  File \"/Users/berkeargin/opt/anaconda3/lib/python3.9/urllib/request.py\", line 632, in http_response\n",
      "    response = self.parent.error(\n",
      "  File \"/Users/berkeargin/opt/anaconda3/lib/python3.9/urllib/request.py\", line 561, in error\n",
      "    return self._call_chain(*args)\n",
      "  File \"/Users/berkeargin/opt/anaconda3/lib/python3.9/urllib/request.py\", line 494, in _call_chain\n",
      "    result = func(*args)\n",
      "  File \"/Users/berkeargin/opt/anaconda3/lib/python3.9/urllib/request.py\", line 641, in http_error_default\n",
      "    raise HTTPError(req.full_url, code, msg, hdrs, fp)\n",
      "urllib.error.HTTPError: HTTP Error 405: Not Allowed\n",
      "2023-11-16 16:51:23,636 CRITICAL [imdbpy] /Users/berkeargin/opt/anaconda3/lib/python3.9/site-packages/imdb/_exceptions.py:32: IMDbDataAccessError exception raised; args: ({'errcode': None, 'errmsg': 'None', 'url': 'https://www.imdb.com/find/?q=Killing+Time+%281998%29&s=tt', 'proxy': '', 'exception type': 'IOError', 'original exception': <HTTPError 405: 'Not Allowed'>},); kwds: {}\n",
      "Traceback (most recent call last):\n",
      "  File \"/Users/berkeargin/opt/anaconda3/lib/python3.9/site-packages/imdb/parser/http/__init__.py\", line 233, in retrieve_unicode\n",
      "    response = uopener.open(url)\n",
      "  File \"/Users/berkeargin/opt/anaconda3/lib/python3.9/urllib/request.py\", line 523, in open\n",
      "    response = meth(req, response)\n",
      "  File \"/Users/berkeargin/opt/anaconda3/lib/python3.9/urllib/request.py\", line 632, in http_response\n",
      "    response = self.parent.error(\n",
      "  File \"/Users/berkeargin/opt/anaconda3/lib/python3.9/urllib/request.py\", line 561, in error\n",
      "    return self._call_chain(*args)\n",
      "  File \"/Users/berkeargin/opt/anaconda3/lib/python3.9/urllib/request.py\", line 494, in _call_chain\n",
      "    result = func(*args)\n",
      "  File \"/Users/berkeargin/opt/anaconda3/lib/python3.9/urllib/request.py\", line 641, in http_error_default\n",
      "    raise HTTPError(req.full_url, code, msg, hdrs, fp)\n",
      "urllib.error.HTTPError: HTTP Error 405: Not Allowed\n",
      "2023-11-16 16:51:26,074 CRITICAL [imdbpy] /Users/berkeargin/opt/anaconda3/lib/python3.9/site-packages/imdb/_exceptions.py:32: IMDbDataAccessError exception raised; args: ({'errcode': None, 'errmsg': 'None', 'url': 'https://www.imdb.com/find/?q=Virus+Diwan+%282011%29&s=tt', 'proxy': '', 'exception type': 'IOError', 'original exception': <HTTPError 502: 'Bad Gateway'>},); kwds: {}\n",
      "Traceback (most recent call last):\n",
      "  File \"/Users/berkeargin/opt/anaconda3/lib/python3.9/site-packages/imdb/parser/http/__init__.py\", line 233, in retrieve_unicode\n",
      "    response = uopener.open(url)\n",
      "  File \"/Users/berkeargin/opt/anaconda3/lib/python3.9/urllib/request.py\", line 523, in open\n",
      "    response = meth(req, response)\n",
      "  File \"/Users/berkeargin/opt/anaconda3/lib/python3.9/urllib/request.py\", line 632, in http_response\n",
      "    response = self.parent.error(\n",
      "  File \"/Users/berkeargin/opt/anaconda3/lib/python3.9/urllib/request.py\", line 561, in error\n",
      "    return self._call_chain(*args)\n",
      "  File \"/Users/berkeargin/opt/anaconda3/lib/python3.9/urllib/request.py\", line 494, in _call_chain\n",
      "    result = func(*args)\n",
      "  File \"/Users/berkeargin/opt/anaconda3/lib/python3.9/urllib/request.py\", line 641, in http_error_default\n",
      "    raise HTTPError(req.full_url, code, msg, hdrs, fp)\n",
      "urllib.error.HTTPError: HTTP Error 502: Bad Gateway\n",
      "2023-11-16 16:51:41,947 CRITICAL [imdbpy] /Users/berkeargin/opt/anaconda3/lib/python3.9/site-packages/imdb/_exceptions.py:32: IMDbDataAccessError exception raised; args: ({'errcode': None, 'errmsg': 'None', 'url': 'https://www.imdb.com/find/?q=Coming+Down+the+Mountain+%28nan%29&s=tt', 'proxy': '', 'exception type': 'IOError', 'original exception': <HTTPError 502: 'Bad Gateway'>},); kwds: {}\n",
      "Traceback (most recent call last):\n",
      "  File \"/Users/berkeargin/opt/anaconda3/lib/python3.9/site-packages/imdb/parser/http/__init__.py\", line 233, in retrieve_unicode\n",
      "    response = uopener.open(url)\n",
      "  File \"/Users/berkeargin/opt/anaconda3/lib/python3.9/urllib/request.py\", line 523, in open\n",
      "    response = meth(req, response)\n",
      "  File \"/Users/berkeargin/opt/anaconda3/lib/python3.9/urllib/request.py\", line 632, in http_response\n",
      "    response = self.parent.error(\n",
      "  File \"/Users/berkeargin/opt/anaconda3/lib/python3.9/urllib/request.py\", line 561, in error\n",
      "    return self._call_chain(*args)\n",
      "  File \"/Users/berkeargin/opt/anaconda3/lib/python3.9/urllib/request.py\", line 494, in _call_chain\n",
      "    result = func(*args)\n",
      "  File \"/Users/berkeargin/opt/anaconda3/lib/python3.9/urllib/request.py\", line 641, in http_error_default\n",
      "    raise HTTPError(req.full_url, code, msg, hdrs, fp)\n",
      "urllib.error.HTTPError: HTTP Error 502: Bad Gateway\n",
      "2023-11-16 16:51:51,151 CRITICAL [imdbpy] /Users/berkeargin/opt/anaconda3/lib/python3.9/site-packages/imdb/_exceptions.py:32: IMDbDataAccessError exception raised; args: ({'errcode': None, 'errmsg': 'None', 'url': 'https://www.imdb.com/find/?q=Porklips+Now+%281980%29&s=tt', 'proxy': '', 'exception type': 'IOError', 'original exception': <HTTPError 405: 'Not Allowed'>},); kwds: {}\n",
      "Traceback (most recent call last):\n",
      "  File \"/Users/berkeargin/opt/anaconda3/lib/python3.9/site-packages/imdb/parser/http/__init__.py\", line 233, in retrieve_unicode\n",
      "    response = uopener.open(url)\n",
      "  File \"/Users/berkeargin/opt/anaconda3/lib/python3.9/urllib/request.py\", line 523, in open\n",
      "    response = meth(req, response)\n",
      "  File \"/Users/berkeargin/opt/anaconda3/lib/python3.9/urllib/request.py\", line 632, in http_response\n",
      "    response = self.parent.error(\n",
      "  File \"/Users/berkeargin/opt/anaconda3/lib/python3.9/urllib/request.py\", line 561, in error\n",
      "    return self._call_chain(*args)\n",
      "  File \"/Users/berkeargin/opt/anaconda3/lib/python3.9/urllib/request.py\", line 494, in _call_chain\n",
      "    result = func(*args)\n",
      "  File \"/Users/berkeargin/opt/anaconda3/lib/python3.9/urllib/request.py\", line 641, in http_error_default\n",
      "    raise HTTPError(req.full_url, code, msg, hdrs, fp)\n",
      "urllib.error.HTTPError: HTTP Error 405: Not Allowed\n",
      "2023-11-16 16:52:46,031 CRITICAL [imdbpy] /Users/berkeargin/opt/anaconda3/lib/python3.9/site-packages/imdb/_exceptions.py:32: IMDbDataAccessError exception raised; args: ({'errcode': None, 'errmsg': 'None', 'url': 'https://www.imdb.com/find/?q=French+Leave+%281937%29&s=tt', 'proxy': '', 'exception type': 'IOError', 'original exception': <HTTPError 405: 'Not Allowed'>},); kwds: {}\n",
      "Traceback (most recent call last):\n",
      "  File \"/Users/berkeargin/opt/anaconda3/lib/python3.9/site-packages/imdb/parser/http/__init__.py\", line 233, in retrieve_unicode\n",
      "    response = uopener.open(url)\n",
      "  File \"/Users/berkeargin/opt/anaconda3/lib/python3.9/urllib/request.py\", line 523, in open\n",
      "    response = meth(req, response)\n",
      "  File \"/Users/berkeargin/opt/anaconda3/lib/python3.9/urllib/request.py\", line 632, in http_response\n",
      "    response = self.parent.error(\n",
      "  File \"/Users/berkeargin/opt/anaconda3/lib/python3.9/urllib/request.py\", line 561, in error\n",
      "    return self._call_chain(*args)\n",
      "  File \"/Users/berkeargin/opt/anaconda3/lib/python3.9/urllib/request.py\", line 494, in _call_chain\n",
      "    result = func(*args)\n",
      "  File \"/Users/berkeargin/opt/anaconda3/lib/python3.9/urllib/request.py\", line 641, in http_error_default\n",
      "    raise HTTPError(req.full_url, code, msg, hdrs, fp)\n",
      "urllib.error.HTTPError: HTTP Error 405: Not Allowed\n",
      "2023-11-16 16:53:42,301 CRITICAL [imdbpy] /Users/berkeargin/opt/anaconda3/lib/python3.9/site-packages/imdb/_exceptions.py:32: IMDbDataAccessError exception raised; args: ({'errcode': None, 'errmsg': 'None', 'url': 'https://www.imdb.com/find/?q=Mr.+Right+%282009%29&s=tt', 'proxy': '', 'exception type': 'IOError', 'original exception': <HTTPError 405: 'Not Allowed'>},); kwds: {}\n",
      "Traceback (most recent call last):\n",
      "  File \"/Users/berkeargin/opt/anaconda3/lib/python3.9/site-packages/imdb/parser/http/__init__.py\", line 233, in retrieve_unicode\n",
      "    response = uopener.open(url)\n",
      "  File \"/Users/berkeargin/opt/anaconda3/lib/python3.9/urllib/request.py\", line 523, in open\n",
      "    response = meth(req, response)\n",
      "  File \"/Users/berkeargin/opt/anaconda3/lib/python3.9/urllib/request.py\", line 632, in http_response\n",
      "    response = self.parent.error(\n",
      "  File \"/Users/berkeargin/opt/anaconda3/lib/python3.9/urllib/request.py\", line 561, in error\n",
      "    return self._call_chain(*args)\n",
      "  File \"/Users/berkeargin/opt/anaconda3/lib/python3.9/urllib/request.py\", line 494, in _call_chain\n",
      "    result = func(*args)\n",
      "  File \"/Users/berkeargin/opt/anaconda3/lib/python3.9/urllib/request.py\", line 641, in http_error_default\n",
      "    raise HTTPError(req.full_url, code, msg, hdrs, fp)\n",
      "urllib.error.HTTPError: HTTP Error 405: Not Allowed\n",
      "2023-11-16 16:53:59,876 CRITICAL [imdbpy] /Users/berkeargin/opt/anaconda3/lib/python3.9/site-packages/imdb/_exceptions.py:32: IMDbDataAccessError exception raised; args: ({'errcode': None, 'errmsg': 'None', 'url': 'https://www.imdb.com/find/?q=The+Strip+%281951%29&s=tt', 'proxy': '', 'exception type': 'IOError', 'original exception': <HTTPError 405: 'Not Allowed'>},); kwds: {}\n",
      "Traceback (most recent call last):\n",
      "  File \"/Users/berkeargin/opt/anaconda3/lib/python3.9/site-packages/imdb/parser/http/__init__.py\", line 233, in retrieve_unicode\n",
      "    response = uopener.open(url)\n",
      "  File \"/Users/berkeargin/opt/anaconda3/lib/python3.9/urllib/request.py\", line 523, in open\n",
      "    response = meth(req, response)\n",
      "  File \"/Users/berkeargin/opt/anaconda3/lib/python3.9/urllib/request.py\", line 632, in http_response\n",
      "    response = self.parent.error(\n",
      "  File \"/Users/berkeargin/opt/anaconda3/lib/python3.9/urllib/request.py\", line 561, in error\n",
      "    return self._call_chain(*args)\n",
      "  File \"/Users/berkeargin/opt/anaconda3/lib/python3.9/urllib/request.py\", line 494, in _call_chain\n",
      "    result = func(*args)\n",
      "  File \"/Users/berkeargin/opt/anaconda3/lib/python3.9/urllib/request.py\", line 641, in http_error_default\n",
      "    raise HTTPError(req.full_url, code, msg, hdrs, fp)\n",
      "urllib.error.HTTPError: HTTP Error 405: Not Allowed\n",
      "2023-11-16 16:54:09,293 CRITICAL [imdbpy] /Users/berkeargin/opt/anaconda3/lib/python3.9/site-packages/imdb/_exceptions.py:32: IMDbDataAccessError exception raised; args: ({'errcode': None, 'errmsg': 'None', 'url': 'https://www.imdb.com/find/?q=Batman%3A+Year+One+%282011%29&s=tt', 'proxy': '', 'exception type': 'IOError', 'original exception': <HTTPError 500: 'Internal Server Error'>},); kwds: {}\n",
      "Traceback (most recent call last):\n",
      "  File \"/Users/berkeargin/opt/anaconda3/lib/python3.9/site-packages/imdb/parser/http/__init__.py\", line 233, in retrieve_unicode\n",
      "    response = uopener.open(url)\n",
      "  File \"/Users/berkeargin/opt/anaconda3/lib/python3.9/urllib/request.py\", line 523, in open\n",
      "    response = meth(req, response)\n",
      "  File \"/Users/berkeargin/opt/anaconda3/lib/python3.9/urllib/request.py\", line 632, in http_response\n",
      "    response = self.parent.error(\n",
      "  File \"/Users/berkeargin/opt/anaconda3/lib/python3.9/urllib/request.py\", line 561, in error\n",
      "    return self._call_chain(*args)\n",
      "  File \"/Users/berkeargin/opt/anaconda3/lib/python3.9/urllib/request.py\", line 494, in _call_chain\n",
      "    result = func(*args)\n",
      "  File \"/Users/berkeargin/opt/anaconda3/lib/python3.9/urllib/request.py\", line 641, in http_error_default\n",
      "    raise HTTPError(req.full_url, code, msg, hdrs, fp)\n",
      "urllib.error.HTTPError: HTTP Error 500: Internal Server Error\n",
      "2023-11-16 16:54:57,733 CRITICAL [imdbpy] /Users/berkeargin/opt/anaconda3/lib/python3.9/site-packages/imdb/_exceptions.py:32: IMDbDataAccessError exception raised; args: ({'errcode': None, 'errmsg': 'None', 'url': 'https://www.imdb.com/find/?q=21+and+Over+%282012%29&s=tt', 'proxy': '', 'exception type': 'IOError', 'original exception': <HTTPError 405: 'Not Allowed'>},); kwds: {}\n",
      "Traceback (most recent call last):\n",
      "  File \"/Users/berkeargin/opt/anaconda3/lib/python3.9/site-packages/imdb/parser/http/__init__.py\", line 233, in retrieve_unicode\n",
      "    response = uopener.open(url)\n",
      "  File \"/Users/berkeargin/opt/anaconda3/lib/python3.9/urllib/request.py\", line 523, in open\n",
      "    response = meth(req, response)\n",
      "  File \"/Users/berkeargin/opt/anaconda3/lib/python3.9/urllib/request.py\", line 632, in http_response\n",
      "    response = self.parent.error(\n",
      "  File \"/Users/berkeargin/opt/anaconda3/lib/python3.9/urllib/request.py\", line 561, in error\n",
      "    return self._call_chain(*args)\n",
      "  File \"/Users/berkeargin/opt/anaconda3/lib/python3.9/urllib/request.py\", line 494, in _call_chain\n",
      "    result = func(*args)\n",
      "  File \"/Users/berkeargin/opt/anaconda3/lib/python3.9/urllib/request.py\", line 641, in http_error_default\n",
      "    raise HTTPError(req.full_url, code, msg, hdrs, fp)\n",
      "urllib.error.HTTPError: HTTP Error 405: Not Allowed\n",
      "2023-11-16 16:55:08,228 CRITICAL [imdbpy] /Users/berkeargin/opt/anaconda3/lib/python3.9/site-packages/imdb/_exceptions.py:32: IMDbDataAccessError exception raised; args: ({'errcode': None, 'errmsg': 'None', 'url': 'https://www.imdb.com/find/?q=Max+%282002%29&s=tt', 'proxy': '', 'exception type': 'IOError', 'original exception': <HTTPError 405: 'Not Allowed'>},); kwds: {}\n",
      "Traceback (most recent call last):\n",
      "  File \"/Users/berkeargin/opt/anaconda3/lib/python3.9/site-packages/imdb/parser/http/__init__.py\", line 233, in retrieve_unicode\n",
      "    response = uopener.open(url)\n",
      "  File \"/Users/berkeargin/opt/anaconda3/lib/python3.9/urllib/request.py\", line 523, in open\n",
      "    response = meth(req, response)\n",
      "  File \"/Users/berkeargin/opt/anaconda3/lib/python3.9/urllib/request.py\", line 632, in http_response\n",
      "    response = self.parent.error(\n",
      "  File \"/Users/berkeargin/opt/anaconda3/lib/python3.9/urllib/request.py\", line 561, in error\n",
      "    return self._call_chain(*args)\n",
      "  File \"/Users/berkeargin/opt/anaconda3/lib/python3.9/urllib/request.py\", line 494, in _call_chain\n",
      "    result = func(*args)\n",
      "  File \"/Users/berkeargin/opt/anaconda3/lib/python3.9/urllib/request.py\", line 641, in http_error_default\n",
      "    raise HTTPError(req.full_url, code, msg, hdrs, fp)\n",
      "urllib.error.HTTPError: HTTP Error 405: Not Allowed\n",
      "2023-11-16 16:55:17,263 CRITICAL [imdbpy] /Users/berkeargin/opt/anaconda3/lib/python3.9/site-packages/imdb/_exceptions.py:32: IMDbDataAccessError exception raised; args: ({'errcode': None, 'errmsg': 'None', 'url': 'https://www.imdb.com/find/?q=Not+Much+Force+%281915%29&s=tt', 'proxy': '', 'exception type': 'IOError', 'original exception': <HTTPError 405: 'Not Allowed'>},); kwds: {}\n",
      "Traceback (most recent call last):\n",
      "  File \"/Users/berkeargin/opt/anaconda3/lib/python3.9/site-packages/imdb/parser/http/__init__.py\", line 233, in retrieve_unicode\n",
      "    response = uopener.open(url)\n",
      "  File \"/Users/berkeargin/opt/anaconda3/lib/python3.9/urllib/request.py\", line 523, in open\n",
      "    response = meth(req, response)\n",
      "  File \"/Users/berkeargin/opt/anaconda3/lib/python3.9/urllib/request.py\", line 632, in http_response\n",
      "    response = self.parent.error(\n",
      "  File \"/Users/berkeargin/opt/anaconda3/lib/python3.9/urllib/request.py\", line 561, in error\n",
      "    return self._call_chain(*args)\n",
      "  File \"/Users/berkeargin/opt/anaconda3/lib/python3.9/urllib/request.py\", line 494, in _call_chain\n",
      "    result = func(*args)\n",
      "  File \"/Users/berkeargin/opt/anaconda3/lib/python3.9/urllib/request.py\", line 641, in http_error_default\n",
      "    raise HTTPError(req.full_url, code, msg, hdrs, fp)\n",
      "urllib.error.HTTPError: HTTP Error 405: Not Allowed\n",
      "2023-11-16 16:57:14,825 CRITICAL [imdbpy] /Users/berkeargin/opt/anaconda3/lib/python3.9/site-packages/imdb/_exceptions.py:32: IMDbDataAccessError exception raised; args: ({'errcode': None, 'errmsg': 'None', 'url': 'https://www.imdb.com/find/?q=Cool+Change+%281986%29&s=tt', 'proxy': '', 'exception type': 'IOError', 'original exception': <HTTPError 405: 'Not Allowed'>},); kwds: {}\n",
      "Traceback (most recent call last):\n",
      "  File \"/Users/berkeargin/opt/anaconda3/lib/python3.9/site-packages/imdb/parser/http/__init__.py\", line 233, in retrieve_unicode\n",
      "    response = uopener.open(url)\n",
      "  File \"/Users/berkeargin/opt/anaconda3/lib/python3.9/urllib/request.py\", line 523, in open\n",
      "    response = meth(req, response)\n",
      "  File \"/Users/berkeargin/opt/anaconda3/lib/python3.9/urllib/request.py\", line 632, in http_response\n",
      "    response = self.parent.error(\n",
      "  File \"/Users/berkeargin/opt/anaconda3/lib/python3.9/urllib/request.py\", line 561, in error\n",
      "    return self._call_chain(*args)\n",
      "  File \"/Users/berkeargin/opt/anaconda3/lib/python3.9/urllib/request.py\", line 494, in _call_chain\n",
      "    result = func(*args)\n",
      "  File \"/Users/berkeargin/opt/anaconda3/lib/python3.9/urllib/request.py\", line 641, in http_error_default\n",
      "    raise HTTPError(req.full_url, code, msg, hdrs, fp)\n",
      "urllib.error.HTTPError: HTTP Error 405: Not Allowed\n",
      "2023-11-16 16:57:25,185 CRITICAL [imdbpy] /Users/berkeargin/opt/anaconda3/lib/python3.9/site-packages/imdb/_exceptions.py:32: IMDbDataAccessError exception raised; args: ({'errcode': None, 'errmsg': 'None', 'url': 'https://www.imdb.com/find/?q=Dogs+in+Space+%281987%29&s=tt', 'proxy': '', 'exception type': 'IOError', 'original exception': <HTTPError 405: 'Not Allowed'>},); kwds: {}\n",
      "Traceback (most recent call last):\n",
      "  File \"/Users/berkeargin/opt/anaconda3/lib/python3.9/site-packages/imdb/parser/http/__init__.py\", line 233, in retrieve_unicode\n",
      "    response = uopener.open(url)\n",
      "  File \"/Users/berkeargin/opt/anaconda3/lib/python3.9/urllib/request.py\", line 523, in open\n",
      "    response = meth(req, response)\n",
      "  File \"/Users/berkeargin/opt/anaconda3/lib/python3.9/urllib/request.py\", line 632, in http_response\n",
      "    response = self.parent.error(\n",
      "  File \"/Users/berkeargin/opt/anaconda3/lib/python3.9/urllib/request.py\", line 561, in error\n",
      "    return self._call_chain(*args)\n",
      "  File \"/Users/berkeargin/opt/anaconda3/lib/python3.9/urllib/request.py\", line 494, in _call_chain\n",
      "    result = func(*args)\n",
      "  File \"/Users/berkeargin/opt/anaconda3/lib/python3.9/urllib/request.py\", line 641, in http_error_default\n",
      "    raise HTTPError(req.full_url, code, msg, hdrs, fp)\n",
      "urllib.error.HTTPError: HTTP Error 405: Not Allowed\n",
      "2023-11-16 16:57:31,777 CRITICAL [imdbpy] /Users/berkeargin/opt/anaconda3/lib/python3.9/site-packages/imdb/_exceptions.py:32: IMDbDataAccessError exception raised; args: ({'errcode': None, 'errmsg': 'None', 'url': 'https://www.imdb.com/find/?q=Towards+the+Light+%281918%29&s=tt', 'proxy': '', 'exception type': 'IOError', 'original exception': <HTTPError 500: 'Internal Server Error'>},); kwds: {}\n",
      "Traceback (most recent call last):\n",
      "  File \"/Users/berkeargin/opt/anaconda3/lib/python3.9/site-packages/imdb/parser/http/__init__.py\", line 233, in retrieve_unicode\n",
      "    response = uopener.open(url)\n",
      "  File \"/Users/berkeargin/opt/anaconda3/lib/python3.9/urllib/request.py\", line 523, in open\n",
      "    response = meth(req, response)\n",
      "  File \"/Users/berkeargin/opt/anaconda3/lib/python3.9/urllib/request.py\", line 632, in http_response\n",
      "    response = self.parent.error(\n",
      "  File \"/Users/berkeargin/opt/anaconda3/lib/python3.9/urllib/request.py\", line 561, in error\n",
      "    return self._call_chain(*args)\n",
      "  File \"/Users/berkeargin/opt/anaconda3/lib/python3.9/urllib/request.py\", line 494, in _call_chain\n",
      "    result = func(*args)\n",
      "  File \"/Users/berkeargin/opt/anaconda3/lib/python3.9/urllib/request.py\", line 641, in http_error_default\n",
      "    raise HTTPError(req.full_url, code, msg, hdrs, fp)\n",
      "urllib.error.HTTPError: HTTP Error 500: Internal Server Error\n",
      "2023-11-16 16:57:35,744 CRITICAL [imdbpy] /Users/berkeargin/opt/anaconda3/lib/python3.9/site-packages/imdb/_exceptions.py:32: IMDbDataAccessError exception raised; args: ({'errcode': None, 'errmsg': 'None', 'url': 'https://www.imdb.com/find/?q=Turkey+Time+%281933%29&s=tt', 'proxy': '', 'exception type': 'IOError', 'original exception': <HTTPError 405: 'Not Allowed'>},); kwds: {}\n",
      "Traceback (most recent call last):\n",
      "  File \"/Users/berkeargin/opt/anaconda3/lib/python3.9/site-packages/imdb/parser/http/__init__.py\", line 233, in retrieve_unicode\n",
      "    response = uopener.open(url)\n",
      "  File \"/Users/berkeargin/opt/anaconda3/lib/python3.9/urllib/request.py\", line 523, in open\n",
      "    response = meth(req, response)\n",
      "  File \"/Users/berkeargin/opt/anaconda3/lib/python3.9/urllib/request.py\", line 632, in http_response\n",
      "    response = self.parent.error(\n",
      "  File \"/Users/berkeargin/opt/anaconda3/lib/python3.9/urllib/request.py\", line 561, in error\n",
      "    return self._call_chain(*args)\n",
      "  File \"/Users/berkeargin/opt/anaconda3/lib/python3.9/urllib/request.py\", line 494, in _call_chain\n",
      "    result = func(*args)\n",
      "  File \"/Users/berkeargin/opt/anaconda3/lib/python3.9/urllib/request.py\", line 641, in http_error_default\n",
      "    raise HTTPError(req.full_url, code, msg, hdrs, fp)\n",
      "urllib.error.HTTPError: HTTP Error 405: Not Allowed\n",
      "2023-11-16 16:57:47,612 CRITICAL [imdbpy] /Users/berkeargin/opt/anaconda3/lib/python3.9/site-packages/imdb/_exceptions.py:32: IMDbDataAccessError exception raised; args: ({'errcode': None, 'errmsg': 'None', 'url': 'https://www.imdb.com/find/?q=Love+and+Money+%281982%29&s=tt', 'proxy': '', 'exception type': 'IOError', 'original exception': <HTTPError 405: 'Not Allowed'>},); kwds: {}\n",
      "Traceback (most recent call last):\n",
      "  File \"/Users/berkeargin/opt/anaconda3/lib/python3.9/site-packages/imdb/parser/http/__init__.py\", line 233, in retrieve_unicode\n",
      "    response = uopener.open(url)\n",
      "  File \"/Users/berkeargin/opt/anaconda3/lib/python3.9/urllib/request.py\", line 523, in open\n",
      "    response = meth(req, response)\n",
      "  File \"/Users/berkeargin/opt/anaconda3/lib/python3.9/urllib/request.py\", line 632, in http_response\n",
      "    response = self.parent.error(\n",
      "  File \"/Users/berkeargin/opt/anaconda3/lib/python3.9/urllib/request.py\", line 561, in error\n",
      "    return self._call_chain(*args)\n",
      "  File \"/Users/berkeargin/opt/anaconda3/lib/python3.9/urllib/request.py\", line 494, in _call_chain\n",
      "    result = func(*args)\n",
      "  File \"/Users/berkeargin/opt/anaconda3/lib/python3.9/urllib/request.py\", line 641, in http_error_default\n",
      "    raise HTTPError(req.full_url, code, msg, hdrs, fp)\n",
      "urllib.error.HTTPError: HTTP Error 405: Not Allowed\n",
      "2023-11-16 16:58:04,848 CRITICAL [imdbpy] /Users/berkeargin/opt/anaconda3/lib/python3.9/site-packages/imdb/_exceptions.py:32: IMDbDataAccessError exception raised; args: ({'errcode': None, 'errmsg': 'None', 'url': 'https://www.imdb.com/find/?q=Rolling+Family+%282004%29&s=tt', 'proxy': '', 'exception type': 'IOError', 'original exception': <HTTPError 405: 'Not Allowed'>},); kwds: {}\n",
      "Traceback (most recent call last):\n",
      "  File \"/Users/berkeargin/opt/anaconda3/lib/python3.9/site-packages/imdb/parser/http/__init__.py\", line 233, in retrieve_unicode\n",
      "    response = uopener.open(url)\n",
      "  File \"/Users/berkeargin/opt/anaconda3/lib/python3.9/urllib/request.py\", line 523, in open\n",
      "    response = meth(req, response)\n",
      "  File \"/Users/berkeargin/opt/anaconda3/lib/python3.9/urllib/request.py\", line 632, in http_response\n",
      "    response = self.parent.error(\n",
      "  File \"/Users/berkeargin/opt/anaconda3/lib/python3.9/urllib/request.py\", line 561, in error\n",
      "    return self._call_chain(*args)\n",
      "  File \"/Users/berkeargin/opt/anaconda3/lib/python3.9/urllib/request.py\", line 494, in _call_chain\n",
      "    result = func(*args)\n",
      "  File \"/Users/berkeargin/opt/anaconda3/lib/python3.9/urllib/request.py\", line 641, in http_error_default\n",
      "    raise HTTPError(req.full_url, code, msg, hdrs, fp)\n",
      "urllib.error.HTTPError: HTTP Error 405: Not Allowed\n",
      "2023-11-16 16:58:05,224 CRITICAL [imdbpy] /Users/berkeargin/opt/anaconda3/lib/python3.9/site-packages/imdb/_exceptions.py:32: IMDbDataAccessError exception raised; args: ({'errcode': None, 'errmsg': 'None', 'url': 'https://www.imdb.com/find/?q=Barnacle+Bill+%281930%29&s=tt', 'proxy': '', 'exception type': 'IOError', 'original exception': <HTTPError 500: 'Internal Server Error'>},); kwds: {}\n",
      "Traceback (most recent call last):\n",
      "  File \"/Users/berkeargin/opt/anaconda3/lib/python3.9/site-packages/imdb/parser/http/__init__.py\", line 233, in retrieve_unicode\n",
      "    response = uopener.open(url)\n",
      "  File \"/Users/berkeargin/opt/anaconda3/lib/python3.9/urllib/request.py\", line 523, in open\n",
      "    response = meth(req, response)\n",
      "  File \"/Users/berkeargin/opt/anaconda3/lib/python3.9/urllib/request.py\", line 632, in http_response\n",
      "    response = self.parent.error(\n",
      "  File \"/Users/berkeargin/opt/anaconda3/lib/python3.9/urllib/request.py\", line 561, in error\n",
      "    return self._call_chain(*args)\n",
      "  File \"/Users/berkeargin/opt/anaconda3/lib/python3.9/urllib/request.py\", line 494, in _call_chain\n",
      "    result = func(*args)\n",
      "  File \"/Users/berkeargin/opt/anaconda3/lib/python3.9/urllib/request.py\", line 641, in http_error_default\n",
      "    raise HTTPError(req.full_url, code, msg, hdrs, fp)\n",
      "urllib.error.HTTPError: HTTP Error 500: Internal Server Error\n",
      "2023-11-16 16:58:25,742 CRITICAL [imdbpy] /Users/berkeargin/opt/anaconda3/lib/python3.9/site-packages/imdb/_exceptions.py:32: IMDbDataAccessError exception raised; args: ({'errcode': None, 'errmsg': 'None', 'url': 'https://www.imdb.com/find/?q=Hi%27-Neighbor%21+%281934%29&s=tt', 'proxy': '', 'exception type': 'IOError', 'original exception': <HTTPError 405: 'Not Allowed'>},); kwds: {}\n",
      "Traceback (most recent call last):\n",
      "  File \"/Users/berkeargin/opt/anaconda3/lib/python3.9/site-packages/imdb/parser/http/__init__.py\", line 233, in retrieve_unicode\n",
      "    response = uopener.open(url)\n",
      "  File \"/Users/berkeargin/opt/anaconda3/lib/python3.9/urllib/request.py\", line 523, in open\n",
      "    response = meth(req, response)\n",
      "  File \"/Users/berkeargin/opt/anaconda3/lib/python3.9/urllib/request.py\", line 632, in http_response\n",
      "    response = self.parent.error(\n",
      "  File \"/Users/berkeargin/opt/anaconda3/lib/python3.9/urllib/request.py\", line 561, in error\n",
      "    return self._call_chain(*args)\n",
      "  File \"/Users/berkeargin/opt/anaconda3/lib/python3.9/urllib/request.py\", line 494, in _call_chain\n",
      "    result = func(*args)\n",
      "  File \"/Users/berkeargin/opt/anaconda3/lib/python3.9/urllib/request.py\", line 641, in http_error_default\n",
      "    raise HTTPError(req.full_url, code, msg, hdrs, fp)\n",
      "urllib.error.HTTPError: HTTP Error 405: Not Allowed\n",
      "2023-11-16 16:58:48,967 CRITICAL [imdbpy] /Users/berkeargin/opt/anaconda3/lib/python3.9/site-packages/imdb/_exceptions.py:32: IMDbDataAccessError exception raised; args: ({'errcode': None, 'errmsg': 'None', 'url': 'https://www.imdb.com/find/?q=Breaking+Point+%282005%29&s=tt', 'proxy': '', 'exception type': 'IOError', 'original exception': <HTTPError 405: 'Not Allowed'>},); kwds: {}\n",
      "Traceback (most recent call last):\n",
      "  File \"/Users/berkeargin/opt/anaconda3/lib/python3.9/site-packages/imdb/parser/http/__init__.py\", line 233, in retrieve_unicode\n",
      "    response = uopener.open(url)\n",
      "  File \"/Users/berkeargin/opt/anaconda3/lib/python3.9/urllib/request.py\", line 523, in open\n",
      "    response = meth(req, response)\n",
      "  File \"/Users/berkeargin/opt/anaconda3/lib/python3.9/urllib/request.py\", line 632, in http_response\n",
      "    response = self.parent.error(\n",
      "  File \"/Users/berkeargin/opt/anaconda3/lib/python3.9/urllib/request.py\", line 561, in error\n",
      "    return self._call_chain(*args)\n",
      "  File \"/Users/berkeargin/opt/anaconda3/lib/python3.9/urllib/request.py\", line 494, in _call_chain\n",
      "    result = func(*args)\n",
      "  File \"/Users/berkeargin/opt/anaconda3/lib/python3.9/urllib/request.py\", line 641, in http_error_default\n",
      "    raise HTTPError(req.full_url, code, msg, hdrs, fp)\n",
      "urllib.error.HTTPError: HTTP Error 405: Not Allowed\n",
      "2023-11-16 16:59:37,458 CRITICAL [imdbpy] /Users/berkeargin/opt/anaconda3/lib/python3.9/site-packages/imdb/_exceptions.py:32: IMDbDataAccessError exception raised; args: ({'errcode': None, 'errmsg': 'None', 'url': 'https://www.imdb.com/find/?q=Blind+Date+%281984%29&s=tt', 'proxy': '', 'exception type': 'IOError', 'original exception': <HTTPError 405: 'Not Allowed'>},); kwds: {}\n",
      "Traceback (most recent call last):\n",
      "  File \"/Users/berkeargin/opt/anaconda3/lib/python3.9/site-packages/imdb/parser/http/__init__.py\", line 233, in retrieve_unicode\n",
      "    response = uopener.open(url)\n",
      "  File \"/Users/berkeargin/opt/anaconda3/lib/python3.9/urllib/request.py\", line 523, in open\n",
      "    response = meth(req, response)\n",
      "  File \"/Users/berkeargin/opt/anaconda3/lib/python3.9/urllib/request.py\", line 632, in http_response\n",
      "    response = self.parent.error(\n",
      "  File \"/Users/berkeargin/opt/anaconda3/lib/python3.9/urllib/request.py\", line 561, in error\n",
      "    return self._call_chain(*args)\n",
      "  File \"/Users/berkeargin/opt/anaconda3/lib/python3.9/urllib/request.py\", line 494, in _call_chain\n",
      "    result = func(*args)\n",
      "  File \"/Users/berkeargin/opt/anaconda3/lib/python3.9/urllib/request.py\", line 641, in http_error_default\n",
      "    raise HTTPError(req.full_url, code, msg, hdrs, fp)\n",
      "urllib.error.HTTPError: HTTP Error 405: Not Allowed\n",
      "2023-11-16 17:00:32,164 CRITICAL [imdbpy] /Users/berkeargin/opt/anaconda3/lib/python3.9/site-packages/imdb/_exceptions.py:32: IMDbDataAccessError exception raised; args: ({'errcode': None, 'errmsg': 'None', 'url': 'https://www.imdb.com/find/?q=Decoys+%282004%29&s=tt', 'proxy': '', 'exception type': 'IOError', 'original exception': <HTTPError 500: 'Internal Server Error'>},); kwds: {}\n",
      "Traceback (most recent call last):\n",
      "  File \"/Users/berkeargin/opt/anaconda3/lib/python3.9/site-packages/imdb/parser/http/__init__.py\", line 233, in retrieve_unicode\n",
      "    response = uopener.open(url)\n",
      "  File \"/Users/berkeargin/opt/anaconda3/lib/python3.9/urllib/request.py\", line 523, in open\n",
      "    response = meth(req, response)\n",
      "  File \"/Users/berkeargin/opt/anaconda3/lib/python3.9/urllib/request.py\", line 632, in http_response\n",
      "    response = self.parent.error(\n",
      "  File \"/Users/berkeargin/opt/anaconda3/lib/python3.9/urllib/request.py\", line 561, in error\n",
      "    return self._call_chain(*args)\n",
      "  File \"/Users/berkeargin/opt/anaconda3/lib/python3.9/urllib/request.py\", line 494, in _call_chain\n",
      "    result = func(*args)\n",
      "  File \"/Users/berkeargin/opt/anaconda3/lib/python3.9/urllib/request.py\", line 641, in http_error_default\n",
      "    raise HTTPError(req.full_url, code, msg, hdrs, fp)\n",
      "urllib.error.HTTPError: HTTP Error 500: Internal Server Error\n",
      "2023-11-16 17:00:36,283 CRITICAL [imdbpy] /Users/berkeargin/opt/anaconda3/lib/python3.9/site-packages/imdb/_exceptions.py:32: IMDbDataAccessError exception raised; args: ({'errcode': None, 'errmsg': 'None', 'url': 'https://www.imdb.com/find/?q=Arbor+Day+%281936%29&s=tt', 'proxy': '', 'exception type': 'IOError', 'original exception': <HTTPError 405: 'Not Allowed'>},); kwds: {}\n",
      "Traceback (most recent call last):\n",
      "  File \"/Users/berkeargin/opt/anaconda3/lib/python3.9/site-packages/imdb/parser/http/__init__.py\", line 233, in retrieve_unicode\n",
      "    response = uopener.open(url)\n",
      "  File \"/Users/berkeargin/opt/anaconda3/lib/python3.9/urllib/request.py\", line 523, in open\n",
      "    response = meth(req, response)\n",
      "  File \"/Users/berkeargin/opt/anaconda3/lib/python3.9/urllib/request.py\", line 632, in http_response\n",
      "    response = self.parent.error(\n",
      "  File \"/Users/berkeargin/opt/anaconda3/lib/python3.9/urllib/request.py\", line 561, in error\n",
      "    return self._call_chain(*args)\n",
      "  File \"/Users/berkeargin/opt/anaconda3/lib/python3.9/urllib/request.py\", line 494, in _call_chain\n",
      "    result = func(*args)\n",
      "  File \"/Users/berkeargin/opt/anaconda3/lib/python3.9/urllib/request.py\", line 641, in http_error_default\n",
      "    raise HTTPError(req.full_url, code, msg, hdrs, fp)\n",
      "urllib.error.HTTPError: HTTP Error 405: Not Allowed\n",
      "2023-11-16 17:00:56,552 CRITICAL [imdbpy] /Users/berkeargin/opt/anaconda3/lib/python3.9/site-packages/imdb/_exceptions.py:32: IMDbDataAccessError exception raised; args: ({'errcode': None, 'errmsg': 'None', 'url': 'https://www.imdb.com/find/?q=Hear+and+Now+%282007%29&s=tt', 'proxy': '', 'exception type': 'IOError', 'original exception': <HTTPError 405: 'Not Allowed'>},); kwds: {}\n",
      "Traceback (most recent call last):\n",
      "  File \"/Users/berkeargin/opt/anaconda3/lib/python3.9/site-packages/imdb/parser/http/__init__.py\", line 233, in retrieve_unicode\n",
      "    response = uopener.open(url)\n",
      "  File \"/Users/berkeargin/opt/anaconda3/lib/python3.9/urllib/request.py\", line 523, in open\n",
      "    response = meth(req, response)\n",
      "  File \"/Users/berkeargin/opt/anaconda3/lib/python3.9/urllib/request.py\", line 632, in http_response\n",
      "    response = self.parent.error(\n",
      "  File \"/Users/berkeargin/opt/anaconda3/lib/python3.9/urllib/request.py\", line 561, in error\n",
      "    return self._call_chain(*args)\n",
      "  File \"/Users/berkeargin/opt/anaconda3/lib/python3.9/urllib/request.py\", line 494, in _call_chain\n",
      "    result = func(*args)\n",
      "  File \"/Users/berkeargin/opt/anaconda3/lib/python3.9/urllib/request.py\", line 641, in http_error_default\n",
      "    raise HTTPError(req.full_url, code, msg, hdrs, fp)\n",
      "urllib.error.HTTPError: HTTP Error 405: Not Allowed\n",
      "2023-11-16 17:01:34,699 CRITICAL [imdbpy] /Users/berkeargin/opt/anaconda3/lib/python3.9/site-packages/imdb/_exceptions.py:32: IMDbDataAccessError exception raised; args: ({'errcode': None, 'errmsg': 'None', 'url': 'https://www.imdb.com/find/?q=Kids+Return+%281996%29&s=tt', 'proxy': '', 'exception type': 'IOError', 'original exception': <HTTPError 405: 'Not Allowed'>},); kwds: {}\n",
      "Traceback (most recent call last):\n",
      "  File \"/Users/berkeargin/opt/anaconda3/lib/python3.9/site-packages/imdb/parser/http/__init__.py\", line 233, in retrieve_unicode\n",
      "    response = uopener.open(url)\n",
      "  File \"/Users/berkeargin/opt/anaconda3/lib/python3.9/urllib/request.py\", line 523, in open\n",
      "    response = meth(req, response)\n",
      "  File \"/Users/berkeargin/opt/anaconda3/lib/python3.9/urllib/request.py\", line 632, in http_response\n",
      "    response = self.parent.error(\n",
      "  File \"/Users/berkeargin/opt/anaconda3/lib/python3.9/urllib/request.py\", line 561, in error\n",
      "    return self._call_chain(*args)\n",
      "  File \"/Users/berkeargin/opt/anaconda3/lib/python3.9/urllib/request.py\", line 494, in _call_chain\n",
      "    result = func(*args)\n",
      "  File \"/Users/berkeargin/opt/anaconda3/lib/python3.9/urllib/request.py\", line 641, in http_error_default\n",
      "    raise HTTPError(req.full_url, code, msg, hdrs, fp)\n",
      "urllib.error.HTTPError: HTTP Error 405: Not Allowed\n",
      "2023-11-16 17:01:40,581 CRITICAL [imdbpy] /Users/berkeargin/opt/anaconda3/lib/python3.9/site-packages/imdb/_exceptions.py:32: IMDbDataAccessError exception raised; args: ({'errcode': None, 'errmsg': 'None', 'url': 'https://www.imdb.com/find/?q=Long+Tan+%282008%29&s=tt', 'proxy': '', 'exception type': 'IOError', 'original exception': <HTTPError 405: 'Not Allowed'>},); kwds: {}\n",
      "Traceback (most recent call last):\n",
      "  File \"/Users/berkeargin/opt/anaconda3/lib/python3.9/site-packages/imdb/parser/http/__init__.py\", line 233, in retrieve_unicode\n",
      "    response = uopener.open(url)\n",
      "  File \"/Users/berkeargin/opt/anaconda3/lib/python3.9/urllib/request.py\", line 523, in open\n",
      "    response = meth(req, response)\n",
      "  File \"/Users/berkeargin/opt/anaconda3/lib/python3.9/urllib/request.py\", line 632, in http_response\n",
      "    response = self.parent.error(\n",
      "  File \"/Users/berkeargin/opt/anaconda3/lib/python3.9/urllib/request.py\", line 561, in error\n",
      "    return self._call_chain(*args)\n",
      "  File \"/Users/berkeargin/opt/anaconda3/lib/python3.9/urllib/request.py\", line 494, in _call_chain\n",
      "    result = func(*args)\n",
      "  File \"/Users/berkeargin/opt/anaconda3/lib/python3.9/urllib/request.py\", line 641, in http_error_default\n",
      "    raise HTTPError(req.full_url, code, msg, hdrs, fp)\n",
      "urllib.error.HTTPError: HTTP Error 405: Not Allowed\n",
      "2023-11-16 17:02:41,779 CRITICAL [imdbpy] /Users/berkeargin/opt/anaconda3/lib/python3.9/site-packages/imdb/_exceptions.py:32: IMDbDataAccessError exception raised; args: ({'errcode': None, 'errmsg': 'None', 'url': 'https://www.imdb.com/find/?q=The+Inner+Circle+%281912%29&s=tt', 'proxy': '', 'exception type': 'IOError', 'original exception': <HTTPError 405: 'Not Allowed'>},); kwds: {}\n",
      "Traceback (most recent call last):\n",
      "  File \"/Users/berkeargin/opt/anaconda3/lib/python3.9/site-packages/imdb/parser/http/__init__.py\", line 233, in retrieve_unicode\n",
      "    response = uopener.open(url)\n",
      "  File \"/Users/berkeargin/opt/anaconda3/lib/python3.9/urllib/request.py\", line 523, in open\n",
      "    response = meth(req, response)\n",
      "  File \"/Users/berkeargin/opt/anaconda3/lib/python3.9/urllib/request.py\", line 632, in http_response\n",
      "    response = self.parent.error(\n",
      "  File \"/Users/berkeargin/opt/anaconda3/lib/python3.9/urllib/request.py\", line 561, in error\n",
      "    return self._call_chain(*args)\n",
      "  File \"/Users/berkeargin/opt/anaconda3/lib/python3.9/urllib/request.py\", line 494, in _call_chain\n",
      "    result = func(*args)\n",
      "  File \"/Users/berkeargin/opt/anaconda3/lib/python3.9/urllib/request.py\", line 641, in http_error_default\n",
      "    raise HTTPError(req.full_url, code, msg, hdrs, fp)\n",
      "urllib.error.HTTPError: HTTP Error 405: Not Allowed\n",
      "2023-11-16 17:02:45,784 CRITICAL [imdbpy] /Users/berkeargin/opt/anaconda3/lib/python3.9/site-packages/imdb/_exceptions.py:32: IMDbDataAccessError exception raised; args: ({'errcode': None, 'errmsg': 'None', 'url': 'https://www.imdb.com/find/?q=Hallucination+Strip+%281975%29&s=tt', 'proxy': '', 'exception type': 'IOError', 'original exception': <HTTPError 405: 'Not Allowed'>},); kwds: {}\n",
      "Traceback (most recent call last):\n",
      "  File \"/Users/berkeargin/opt/anaconda3/lib/python3.9/site-packages/imdb/parser/http/__init__.py\", line 233, in retrieve_unicode\n",
      "    response = uopener.open(url)\n",
      "  File \"/Users/berkeargin/opt/anaconda3/lib/python3.9/urllib/request.py\", line 523, in open\n",
      "    response = meth(req, response)\n",
      "  File \"/Users/berkeargin/opt/anaconda3/lib/python3.9/urllib/request.py\", line 632, in http_response\n",
      "    response = self.parent.error(\n",
      "  File \"/Users/berkeargin/opt/anaconda3/lib/python3.9/urllib/request.py\", line 561, in error\n",
      "    return self._call_chain(*args)\n",
      "  File \"/Users/berkeargin/opt/anaconda3/lib/python3.9/urllib/request.py\", line 494, in _call_chain\n",
      "    result = func(*args)\n",
      "  File \"/Users/berkeargin/opt/anaconda3/lib/python3.9/urllib/request.py\", line 641, in http_error_default\n",
      "    raise HTTPError(req.full_url, code, msg, hdrs, fp)\n",
      "urllib.error.HTTPError: HTTP Error 405: Not Allowed\n"
     ]
    },
    {
     "ename": "KeyboardInterrupt",
     "evalue": "",
     "output_type": "error",
     "traceback": [
      "\u001b[0;31m---------------------------------------------------------------------------\u001b[0m",
      "\u001b[0;31mKeyboardInterrupt\u001b[0m                         Traceback (most recent call last)",
      "\u001b[0;32m/var/folders/l1/8zt_lx6x0814k8sr48r34sk00000gn/T/ipykernel_64156/1720237232.py\u001b[0m in \u001b[0;36m<module>\u001b[0;34m\u001b[0m\n\u001b[1;32m      1\u001b[0m \u001b[0;31m#Selected only first 1000 for demo -> takes around ~3min\u001b[0m\u001b[0;34m\u001b[0m\u001b[0;34m\u001b[0m\u001b[0m\n\u001b[0;32m----> 2\u001b[0;31m \u001b[0mresponses\u001b[0m\u001b[0;34m=\u001b[0m\u001b[0mret_imdb_data_parallel\u001b[0m\u001b[0;34m(\u001b[0m\u001b[0;36m10\u001b[0m\u001b[0;34m,\u001b[0m\u001b[0mmovies\u001b[0m\u001b[0;34m.\u001b[0m\u001b[0miloc\u001b[0m\u001b[0;34m[\u001b[0m\u001b[0;36m40000\u001b[0m\u001b[0;34m:\u001b[0m\u001b[0;34m]\u001b[0m\u001b[0;34m)\u001b[0m\u001b[0;34m\u001b[0m\u001b[0;34m\u001b[0m\u001b[0m\n\u001b[0m",
      "\u001b[0;32m~/Documents/GitHub/ada-2023-project-preprocessedpeoples/tools/imdb_multproc.py\u001b[0m in \u001b[0;36mret_imdb_data_parallel\u001b[0;34m(N, dataset, retrieve_with)\u001b[0m\n\u001b[1;32m     46\u001b[0m \u001b[0;34m\u001b[0m\u001b[0m\n\u001b[1;32m     47\u001b[0m     \u001b[0;32mfor\u001b[0m \u001b[0mp\u001b[0m \u001b[0;32min\u001b[0m \u001b[0mprocesses\u001b[0m\u001b[0;34m:\u001b[0m\u001b[0;34m\u001b[0m\u001b[0;34m\u001b[0m\u001b[0m\n\u001b[0;32m---> 48\u001b[0;31m         \u001b[0mp\u001b[0m\u001b[0;34m.\u001b[0m\u001b[0mjoin\u001b[0m\u001b[0;34m(\u001b[0m\u001b[0;34m)\u001b[0m\u001b[0;34m\u001b[0m\u001b[0;34m\u001b[0m\u001b[0m\n\u001b[0m\u001b[1;32m     49\u001b[0m \u001b[0;34m\u001b[0m\u001b[0m\n\u001b[1;32m     50\u001b[0m     \u001b[0mresults\u001b[0m\u001b[0;34m=\u001b[0m\u001b[0;34m[\u001b[0m\u001b[0;34m]\u001b[0m\u001b[0;34m\u001b[0m\u001b[0;34m\u001b[0m\u001b[0m\n",
      "\u001b[0;32m~/opt/anaconda3/lib/python3.9/multiprocessing/process.py\u001b[0m in \u001b[0;36mjoin\u001b[0;34m(self, timeout)\u001b[0m\n\u001b[1;32m    147\u001b[0m         \u001b[0;32massert\u001b[0m \u001b[0mself\u001b[0m\u001b[0;34m.\u001b[0m\u001b[0m_parent_pid\u001b[0m \u001b[0;34m==\u001b[0m \u001b[0mos\u001b[0m\u001b[0;34m.\u001b[0m\u001b[0mgetpid\u001b[0m\u001b[0;34m(\u001b[0m\u001b[0;34m)\u001b[0m\u001b[0;34m,\u001b[0m \u001b[0;34m'can only join a child process'\u001b[0m\u001b[0;34m\u001b[0m\u001b[0;34m\u001b[0m\u001b[0m\n\u001b[1;32m    148\u001b[0m         \u001b[0;32massert\u001b[0m \u001b[0mself\u001b[0m\u001b[0;34m.\u001b[0m\u001b[0m_popen\u001b[0m \u001b[0;32mis\u001b[0m \u001b[0;32mnot\u001b[0m \u001b[0;32mNone\u001b[0m\u001b[0;34m,\u001b[0m \u001b[0;34m'can only join a started process'\u001b[0m\u001b[0;34m\u001b[0m\u001b[0;34m\u001b[0m\u001b[0m\n\u001b[0;32m--> 149\u001b[0;31m         \u001b[0mres\u001b[0m \u001b[0;34m=\u001b[0m \u001b[0mself\u001b[0m\u001b[0;34m.\u001b[0m\u001b[0m_popen\u001b[0m\u001b[0;34m.\u001b[0m\u001b[0mwait\u001b[0m\u001b[0;34m(\u001b[0m\u001b[0mtimeout\u001b[0m\u001b[0;34m)\u001b[0m\u001b[0;34m\u001b[0m\u001b[0;34m\u001b[0m\u001b[0m\n\u001b[0m\u001b[1;32m    150\u001b[0m         \u001b[0;32mif\u001b[0m \u001b[0mres\u001b[0m \u001b[0;32mis\u001b[0m \u001b[0;32mnot\u001b[0m \u001b[0;32mNone\u001b[0m\u001b[0;34m:\u001b[0m\u001b[0;34m\u001b[0m\u001b[0;34m\u001b[0m\u001b[0m\n\u001b[1;32m    151\u001b[0m             \u001b[0m_children\u001b[0m\u001b[0;34m.\u001b[0m\u001b[0mdiscard\u001b[0m\u001b[0;34m(\u001b[0m\u001b[0mself\u001b[0m\u001b[0;34m)\u001b[0m\u001b[0;34m\u001b[0m\u001b[0;34m\u001b[0m\u001b[0m\n",
      "\u001b[0;32m~/opt/anaconda3/lib/python3.9/multiprocessing/popen_fork.py\u001b[0m in \u001b[0;36mwait\u001b[0;34m(self, timeout)\u001b[0m\n\u001b[1;32m     41\u001b[0m                     \u001b[0;32mreturn\u001b[0m \u001b[0;32mNone\u001b[0m\u001b[0;34m\u001b[0m\u001b[0;34m\u001b[0m\u001b[0m\n\u001b[1;32m     42\u001b[0m             \u001b[0;31m# This shouldn't block if wait() returned successfully.\u001b[0m\u001b[0;34m\u001b[0m\u001b[0;34m\u001b[0m\u001b[0m\n\u001b[0;32m---> 43\u001b[0;31m             \u001b[0;32mreturn\u001b[0m \u001b[0mself\u001b[0m\u001b[0;34m.\u001b[0m\u001b[0mpoll\u001b[0m\u001b[0;34m(\u001b[0m\u001b[0mos\u001b[0m\u001b[0;34m.\u001b[0m\u001b[0mWNOHANG\u001b[0m \u001b[0;32mif\u001b[0m \u001b[0mtimeout\u001b[0m \u001b[0;34m==\u001b[0m \u001b[0;36m0.0\u001b[0m \u001b[0;32melse\u001b[0m \u001b[0;36m0\u001b[0m\u001b[0;34m)\u001b[0m\u001b[0;34m\u001b[0m\u001b[0;34m\u001b[0m\u001b[0m\n\u001b[0m\u001b[1;32m     44\u001b[0m         \u001b[0;32mreturn\u001b[0m \u001b[0mself\u001b[0m\u001b[0;34m.\u001b[0m\u001b[0mreturncode\u001b[0m\u001b[0;34m\u001b[0m\u001b[0;34m\u001b[0m\u001b[0m\n\u001b[1;32m     45\u001b[0m \u001b[0;34m\u001b[0m\u001b[0m\n",
      "\u001b[0;32m~/opt/anaconda3/lib/python3.9/multiprocessing/popen_fork.py\u001b[0m in \u001b[0;36mpoll\u001b[0;34m(self, flag)\u001b[0m\n\u001b[1;32m     25\u001b[0m         \u001b[0;32mif\u001b[0m \u001b[0mself\u001b[0m\u001b[0;34m.\u001b[0m\u001b[0mreturncode\u001b[0m \u001b[0;32mis\u001b[0m \u001b[0;32mNone\u001b[0m\u001b[0;34m:\u001b[0m\u001b[0;34m\u001b[0m\u001b[0;34m\u001b[0m\u001b[0m\n\u001b[1;32m     26\u001b[0m             \u001b[0;32mtry\u001b[0m\u001b[0;34m:\u001b[0m\u001b[0;34m\u001b[0m\u001b[0;34m\u001b[0m\u001b[0m\n\u001b[0;32m---> 27\u001b[0;31m                 \u001b[0mpid\u001b[0m\u001b[0;34m,\u001b[0m \u001b[0msts\u001b[0m \u001b[0;34m=\u001b[0m \u001b[0mos\u001b[0m\u001b[0;34m.\u001b[0m\u001b[0mwaitpid\u001b[0m\u001b[0;34m(\u001b[0m\u001b[0mself\u001b[0m\u001b[0;34m.\u001b[0m\u001b[0mpid\u001b[0m\u001b[0;34m,\u001b[0m \u001b[0mflag\u001b[0m\u001b[0;34m)\u001b[0m\u001b[0;34m\u001b[0m\u001b[0;34m\u001b[0m\u001b[0m\n\u001b[0m\u001b[1;32m     28\u001b[0m             \u001b[0;32mexcept\u001b[0m \u001b[0mOSError\u001b[0m\u001b[0;34m:\u001b[0m\u001b[0;34m\u001b[0m\u001b[0;34m\u001b[0m\u001b[0m\n\u001b[1;32m     29\u001b[0m                 \u001b[0;31m# Child process not yet created. See #1731717\u001b[0m\u001b[0;34m\u001b[0m\u001b[0;34m\u001b[0m\u001b[0m\n",
      "\u001b[0;31mKeyboardInterrupt\u001b[0m: "
     ]
    },
    {
     "name": "stderr",
     "output_type": "stream",
     "text": [
      "2023-11-16 17:03:36,988 CRITICAL [imdbpy] /Users/berkeargin/opt/anaconda3/lib/python3.9/site-packages/imdb/_exceptions.py:32: IMDbDataAccessError exception raised; args: ({'errcode': None, 'errmsg': 'None', 'url': 'https://www.imdb.com/find/?q=Somewhere+in+England+%281940%29&s=tt', 'proxy': '', 'exception type': 'IOError', 'original exception': <HTTPError 502: 'Bad Gateway'>},); kwds: {}\n",
      "Traceback (most recent call last):\n",
      "  File \"/Users/berkeargin/opt/anaconda3/lib/python3.9/site-packages/imdb/parser/http/__init__.py\", line 233, in retrieve_unicode\n",
      "    response = uopener.open(url)\n",
      "  File \"/Users/berkeargin/opt/anaconda3/lib/python3.9/urllib/request.py\", line 523, in open\n",
      "    response = meth(req, response)\n",
      "  File \"/Users/berkeargin/opt/anaconda3/lib/python3.9/urllib/request.py\", line 632, in http_response\n",
      "    response = self.parent.error(\n",
      "  File \"/Users/berkeargin/opt/anaconda3/lib/python3.9/urllib/request.py\", line 561, in error\n",
      "    return self._call_chain(*args)\n",
      "  File \"/Users/berkeargin/opt/anaconda3/lib/python3.9/urllib/request.py\", line 494, in _call_chain\n",
      "    result = func(*args)\n",
      "  File \"/Users/berkeargin/opt/anaconda3/lib/python3.9/urllib/request.py\", line 641, in http_error_default\n",
      "    raise HTTPError(req.full_url, code, msg, hdrs, fp)\n",
      "urllib.error.HTTPError: HTTP Error 502: Bad Gateway\n",
      "2023-11-16 17:03:52,723 CRITICAL [imdbpy] /Users/berkeargin/opt/anaconda3/lib/python3.9/site-packages/imdb/_exceptions.py:32: IMDbDataAccessError exception raised; args: ({'errcode': None, 'errmsg': 'None', 'url': 'https://www.imdb.com/find/?q=Decoration+Day+%281990%29&s=tt', 'proxy': '', 'exception type': 'IOError', 'original exception': <HTTPError 405: 'Not Allowed'>},); kwds: {}\n",
      "Traceback (most recent call last):\n",
      "  File \"/Users/berkeargin/opt/anaconda3/lib/python3.9/site-packages/imdb/parser/http/__init__.py\", line 233, in retrieve_unicode\n",
      "    response = uopener.open(url)\n",
      "  File \"/Users/berkeargin/opt/anaconda3/lib/python3.9/urllib/request.py\", line 523, in open\n",
      "    response = meth(req, response)\n",
      "  File \"/Users/berkeargin/opt/anaconda3/lib/python3.9/urllib/request.py\", line 632, in http_response\n",
      "    response = self.parent.error(\n",
      "  File \"/Users/berkeargin/opt/anaconda3/lib/python3.9/urllib/request.py\", line 561, in error\n",
      "    return self._call_chain(*args)\n",
      "  File \"/Users/berkeargin/opt/anaconda3/lib/python3.9/urllib/request.py\", line 494, in _call_chain\n",
      "    result = func(*args)\n",
      "  File \"/Users/berkeargin/opt/anaconda3/lib/python3.9/urllib/request.py\", line 641, in http_error_default\n",
      "    raise HTTPError(req.full_url, code, msg, hdrs, fp)\n",
      "urllib.error.HTTPError: HTTP Error 405: Not Allowed\n",
      "2023-11-16 17:04:15,394 CRITICAL [imdbpy] /Users/berkeargin/opt/anaconda3/lib/python3.9/site-packages/imdb/_exceptions.py:32: IMDbDataAccessError exception raised; args: ({'errcode': None, 'errmsg': 'None', 'url': 'https://www.imdb.com/find/?q=Full+Circle+%281993%29&s=tt', 'proxy': '', 'exception type': 'IOError', 'original exception': <HTTPError 405: 'Not Allowed'>},); kwds: {}\n",
      "Traceback (most recent call last):\n",
      "  File \"/Users/berkeargin/opt/anaconda3/lib/python3.9/site-packages/imdb/parser/http/__init__.py\", line 233, in retrieve_unicode\n",
      "    response = uopener.open(url)\n",
      "  File \"/Users/berkeargin/opt/anaconda3/lib/python3.9/urllib/request.py\", line 523, in open\n",
      "    response = meth(req, response)\n",
      "  File \"/Users/berkeargin/opt/anaconda3/lib/python3.9/urllib/request.py\", line 632, in http_response\n",
      "    response = self.parent.error(\n",
      "  File \"/Users/berkeargin/opt/anaconda3/lib/python3.9/urllib/request.py\", line 561, in error\n",
      "    return self._call_chain(*args)\n",
      "  File \"/Users/berkeargin/opt/anaconda3/lib/python3.9/urllib/request.py\", line 494, in _call_chain\n",
      "    result = func(*args)\n",
      "  File \"/Users/berkeargin/opt/anaconda3/lib/python3.9/urllib/request.py\", line 641, in http_error_default\n",
      "    raise HTTPError(req.full_url, code, msg, hdrs, fp)\n",
      "urllib.error.HTTPError: HTTP Error 405: Not Allowed\n",
      "2023-11-16 17:04:51,934 CRITICAL [imdbpy] /Users/berkeargin/opt/anaconda3/lib/python3.9/site-packages/imdb/_exceptions.py:32: IMDbDataAccessError exception raised; args: ({'errcode': None, 'errmsg': 'None', 'url': 'https://www.imdb.com/find/?q=Match+Point+%282005%29&s=tt', 'proxy': '', 'exception type': 'IOError', 'original exception': <HTTPError 405: 'Not Allowed'>},); kwds: {}\n",
      "Traceback (most recent call last):\n",
      "  File \"/Users/berkeargin/opt/anaconda3/lib/python3.9/site-packages/imdb/parser/http/__init__.py\", line 233, in retrieve_unicode\n",
      "    response = uopener.open(url)\n",
      "  File \"/Users/berkeargin/opt/anaconda3/lib/python3.9/urllib/request.py\", line 523, in open\n",
      "    response = meth(req, response)\n",
      "  File \"/Users/berkeargin/opt/anaconda3/lib/python3.9/urllib/request.py\", line 632, in http_response\n",
      "    response = self.parent.error(\n",
      "  File \"/Users/berkeargin/opt/anaconda3/lib/python3.9/urllib/request.py\", line 561, in error\n",
      "    return self._call_chain(*args)\n",
      "  File \"/Users/berkeargin/opt/anaconda3/lib/python3.9/urllib/request.py\", line 494, in _call_chain\n",
      "    result = func(*args)\n",
      "  File \"/Users/berkeargin/opt/anaconda3/lib/python3.9/urllib/request.py\", line 641, in http_error_default\n",
      "    raise HTTPError(req.full_url, code, msg, hdrs, fp)\n",
      "urllib.error.HTTPError: HTTP Error 405: Not Allowed\n",
      "2023-11-16 17:05:10,119 CRITICAL [imdbpy] /Users/berkeargin/opt/anaconda3/lib/python3.9/site-packages/imdb/_exceptions.py:32: IMDbDataAccessError exception raised; args: ({'errcode': None, 'errmsg': 'None', 'url': 'https://www.imdb.com/find/?q=Kovak+Box+%282006%29&s=tt', 'proxy': '', 'exception type': 'IOError', 'original exception': <HTTPError 405: 'Not Allowed'>},); kwds: {}\n",
      "Traceback (most recent call last):\n",
      "  File \"/Users/berkeargin/opt/anaconda3/lib/python3.9/site-packages/imdb/parser/http/__init__.py\", line 233, in retrieve_unicode\n",
      "    response = uopener.open(url)\n",
      "  File \"/Users/berkeargin/opt/anaconda3/lib/python3.9/urllib/request.py\", line 523, in open\n",
      "    response = meth(req, response)\n",
      "  File \"/Users/berkeargin/opt/anaconda3/lib/python3.9/urllib/request.py\", line 632, in http_response\n",
      "    response = self.parent.error(\n",
      "  File \"/Users/berkeargin/opt/anaconda3/lib/python3.9/urllib/request.py\", line 561, in error\n",
      "    return self._call_chain(*args)\n",
      "  File \"/Users/berkeargin/opt/anaconda3/lib/python3.9/urllib/request.py\", line 494, in _call_chain\n",
      "    result = func(*args)\n",
      "  File \"/Users/berkeargin/opt/anaconda3/lib/python3.9/urllib/request.py\", line 641, in http_error_default\n",
      "    raise HTTPError(req.full_url, code, msg, hdrs, fp)\n",
      "urllib.error.HTTPError: HTTP Error 405: Not Allowed\n",
      "2023-11-16 17:05:10,229 CRITICAL [imdbpy] /Users/berkeargin/opt/anaconda3/lib/python3.9/site-packages/imdb/_exceptions.py:32: IMDbDataAccessError exception raised; args: ({'errcode': None, 'errmsg': 'None', 'url': 'https://www.imdb.com/find/?q=Lottery+Ticket+%282010%29&s=tt', 'proxy': '', 'exception type': 'IOError', 'original exception': <HTTPError 500: 'Internal Server Error'>},); kwds: {}\n",
      "Traceback (most recent call last):\n",
      "  File \"/Users/berkeargin/opt/anaconda3/lib/python3.9/site-packages/imdb/parser/http/__init__.py\", line 233, in retrieve_unicode\n",
      "    response = uopener.open(url)\n",
      "  File \"/Users/berkeargin/opt/anaconda3/lib/python3.9/urllib/request.py\", line 523, in open\n",
      "    response = meth(req, response)\n",
      "  File \"/Users/berkeargin/opt/anaconda3/lib/python3.9/urllib/request.py\", line 632, in http_response\n",
      "    response = self.parent.error(\n",
      "  File \"/Users/berkeargin/opt/anaconda3/lib/python3.9/urllib/request.py\", line 561, in error\n",
      "    return self._call_chain(*args)\n",
      "  File \"/Users/berkeargin/opt/anaconda3/lib/python3.9/urllib/request.py\", line 494, in _call_chain\n",
      "    result = func(*args)\n",
      "  File \"/Users/berkeargin/opt/anaconda3/lib/python3.9/urllib/request.py\", line 641, in http_error_default\n",
      "    raise HTTPError(req.full_url, code, msg, hdrs, fp)\n",
      "urllib.error.HTTPError: HTTP Error 500: Internal Server Error\n",
      "2023-11-16 17:05:37,416 CRITICAL [imdbpy] /Users/berkeargin/opt/anaconda3/lib/python3.9/site-packages/imdb/_exceptions.py:32: IMDbDataAccessError exception raised; args: ({'errcode': None, 'errmsg': 'None', 'url': 'https://www.imdb.com/find/?q=Independence+Day+%281996%29&s=tt', 'proxy': '', 'exception type': 'IOError', 'original exception': <HTTPError 405: 'Not Allowed'>},); kwds: {}\n",
      "Traceback (most recent call last):\n",
      "  File \"/Users/berkeargin/opt/anaconda3/lib/python3.9/site-packages/imdb/parser/http/__init__.py\", line 233, in retrieve_unicode\n",
      "    response = uopener.open(url)\n",
      "  File \"/Users/berkeargin/opt/anaconda3/lib/python3.9/urllib/request.py\", line 523, in open\n",
      "    response = meth(req, response)\n",
      "  File \"/Users/berkeargin/opt/anaconda3/lib/python3.9/urllib/request.py\", line 632, in http_response\n",
      "    response = self.parent.error(\n",
      "  File \"/Users/berkeargin/opt/anaconda3/lib/python3.9/urllib/request.py\", line 561, in error\n",
      "    return self._call_chain(*args)\n",
      "  File \"/Users/berkeargin/opt/anaconda3/lib/python3.9/urllib/request.py\", line 494, in _call_chain\n",
      "    result = func(*args)\n",
      "  File \"/Users/berkeargin/opt/anaconda3/lib/python3.9/urllib/request.py\", line 641, in http_error_default\n",
      "    raise HTTPError(req.full_url, code, msg, hdrs, fp)\n",
      "urllib.error.HTTPError: HTTP Error 405: Not Allowed\n",
      "2023-11-16 17:05:57,973 CRITICAL [imdbpy] /Users/berkeargin/opt/anaconda3/lib/python3.9/site-packages/imdb/_exceptions.py:32: IMDbDataAccessError exception raised; args: ({'errcode': None, 'errmsg': 'None', 'url': 'https://www.imdb.com/find/?q=Lawless+Range+%281935%29&s=tt', 'proxy': '', 'exception type': 'IOError', 'original exception': <HTTPError 405: 'Not Allowed'>},); kwds: {}\n",
      "Traceback (most recent call last):\n",
      "  File \"/Users/berkeargin/opt/anaconda3/lib/python3.9/site-packages/imdb/parser/http/__init__.py\", line 233, in retrieve_unicode\n",
      "    response = uopener.open(url)\n",
      "  File \"/Users/berkeargin/opt/anaconda3/lib/python3.9/urllib/request.py\", line 523, in open\n",
      "    response = meth(req, response)\n",
      "  File \"/Users/berkeargin/opt/anaconda3/lib/python3.9/urllib/request.py\", line 632, in http_response\n",
      "    response = self.parent.error(\n",
      "  File \"/Users/berkeargin/opt/anaconda3/lib/python3.9/urllib/request.py\", line 561, in error\n",
      "    return self._call_chain(*args)\n",
      "  File \"/Users/berkeargin/opt/anaconda3/lib/python3.9/urllib/request.py\", line 494, in _call_chain\n",
      "    result = func(*args)\n",
      "  File \"/Users/berkeargin/opt/anaconda3/lib/python3.9/urllib/request.py\", line 641, in http_error_default\n",
      "    raise HTTPError(req.full_url, code, msg, hdrs, fp)\n",
      "urllib.error.HTTPError: HTTP Error 405: Not Allowed\n",
      "2023-11-16 17:06:12,341 CRITICAL [imdbpy] /Users/berkeargin/opt/anaconda3/lib/python3.9/site-packages/imdb/_exceptions.py:32: IMDbDataAccessError exception raised; args: ({'errcode': None, 'errmsg': 'None', 'url': 'https://www.imdb.com/find/?q=Sorority+Row+%282009%29&s=tt', 'proxy': '', 'exception type': 'IOError', 'original exception': <HTTPError 405: 'Not Allowed'>},); kwds: {}\n",
      "Traceback (most recent call last):\n",
      "  File \"/Users/berkeargin/opt/anaconda3/lib/python3.9/site-packages/imdb/parser/http/__init__.py\", line 233, in retrieve_unicode\n",
      "    response = uopener.open(url)\n",
      "  File \"/Users/berkeargin/opt/anaconda3/lib/python3.9/urllib/request.py\", line 523, in open\n",
      "    response = meth(req, response)\n",
      "  File \"/Users/berkeargin/opt/anaconda3/lib/python3.9/urllib/request.py\", line 632, in http_response\n",
      "    response = self.parent.error(\n",
      "  File \"/Users/berkeargin/opt/anaconda3/lib/python3.9/urllib/request.py\", line 561, in error\n",
      "    return self._call_chain(*args)\n",
      "  File \"/Users/berkeargin/opt/anaconda3/lib/python3.9/urllib/request.py\", line 494, in _call_chain\n",
      "    result = func(*args)\n",
      "  File \"/Users/berkeargin/opt/anaconda3/lib/python3.9/urllib/request.py\", line 641, in http_error_default\n",
      "    raise HTTPError(req.full_url, code, msg, hdrs, fp)\n",
      "urllib.error.HTTPError: HTTP Error 405: Not Allowed\n",
      "2023-11-16 17:06:19,623 CRITICAL [imdbpy] /Users/berkeargin/opt/anaconda3/lib/python3.9/site-packages/imdb/_exceptions.py:32: IMDbDataAccessError exception raised; args: ({'errcode': None, 'errmsg': 'None', 'url': 'https://www.imdb.com/find/?q=Mayflower%3A+The+Pilgrims%27+Adventure+%281979%29&s=tt', 'proxy': '', 'exception type': 'IOError', 'original exception': <HTTPError 500: 'Internal Server Error'>},); kwds: {}\n",
      "Traceback (most recent call last):\n",
      "  File \"/Users/berkeargin/opt/anaconda3/lib/python3.9/site-packages/imdb/parser/http/__init__.py\", line 233, in retrieve_unicode\n",
      "    response = uopener.open(url)\n",
      "  File \"/Users/berkeargin/opt/anaconda3/lib/python3.9/urllib/request.py\", line 523, in open\n",
      "    response = meth(req, response)\n",
      "  File \"/Users/berkeargin/opt/anaconda3/lib/python3.9/urllib/request.py\", line 632, in http_response\n",
      "    response = self.parent.error(\n",
      "  File \"/Users/berkeargin/opt/anaconda3/lib/python3.9/urllib/request.py\", line 561, in error\n",
      "    return self._call_chain(*args)\n",
      "  File \"/Users/berkeargin/opt/anaconda3/lib/python3.9/urllib/request.py\", line 494, in _call_chain\n",
      "    result = func(*args)\n",
      "  File \"/Users/berkeargin/opt/anaconda3/lib/python3.9/urllib/request.py\", line 641, in http_error_default\n",
      "    raise HTTPError(req.full_url, code, msg, hdrs, fp)\n",
      "urllib.error.HTTPError: HTTP Error 500: Internal Server Error\n",
      "2023-11-16 17:06:30,024 CRITICAL [imdbpy] /Users/berkeargin/opt/anaconda3/lib/python3.9/site-packages/imdb/_exceptions.py:32: IMDbDataAccessError exception raised; args: ({'errcode': None, 'errmsg': 'None', 'url': 'https://www.imdb.com/find/?q=Merry-Go-Round+%281981%29&s=tt', 'proxy': '', 'exception type': 'IOError', 'original exception': <HTTPError 405: 'Not Allowed'>},); kwds: {}\n",
      "Traceback (most recent call last):\n",
      "  File \"/Users/berkeargin/opt/anaconda3/lib/python3.9/site-packages/imdb/parser/http/__init__.py\", line 233, in retrieve_unicode\n",
      "    response = uopener.open(url)\n",
      "  File \"/Users/berkeargin/opt/anaconda3/lib/python3.9/urllib/request.py\", line 523, in open\n",
      "    response = meth(req, response)\n",
      "  File \"/Users/berkeargin/opt/anaconda3/lib/python3.9/urllib/request.py\", line 632, in http_response\n",
      "    response = self.parent.error(\n",
      "  File \"/Users/berkeargin/opt/anaconda3/lib/python3.9/urllib/request.py\", line 561, in error\n",
      "    return self._call_chain(*args)\n",
      "  File \"/Users/berkeargin/opt/anaconda3/lib/python3.9/urllib/request.py\", line 494, in _call_chain\n",
      "    result = func(*args)\n",
      "  File \"/Users/berkeargin/opt/anaconda3/lib/python3.9/urllib/request.py\", line 641, in http_error_default\n",
      "    raise HTTPError(req.full_url, code, msg, hdrs, fp)\n",
      "urllib.error.HTTPError: HTTP Error 405: Not Allowed\n"
     ]
    }
   ],
   "source": [
    "#Selected only first 1000 for demo -> takes around ~3min\n",
    "responses=ret_imdb_data_parallel(10,movies)"
   ]
  },
  {
   "cell_type": "code",
   "execution_count": 5,
   "metadata": {},
   "outputs": [],
   "source": [
    "responses=pd.read_pickle(\"all_imdb_responses.pkl\")\n",
    "\n",
    "ids=[r if type(r)==str else \"tt\"+r.movieID for r in responses]\n",
    "years=[r if type(r)==str else r.get(\"year\") for r in responses]\n",
    "\n",
    "movies[\"imdb_id\"]=ids"
   ]
  },
  {
   "cell_type": "code",
   "execution_count": 4,
   "metadata": {},
   "outputs": [],
   "source": [
    "mismatch_v=[]\n",
    "mismatch_tr=[]\n",
    "for y_1,y_2 in zip(years,movies.iloc[:][\"Movie release date\"].str[:4]):\n",
    "    if str(y_1)!=str(y_2) and len(str(y_2))>3:\n",
    "        mismatch_v.append((y_1,y_2))\n",
    "        try:\n",
    "            if np.abs(int(y_1)-int(y_2))>1:\n",
    "                mismatch_tr.append((y_1,y_2))\n",
    "        except:\n",
    "            continue"
   ]
  },
  {
   "cell_type": "code",
   "execution_count": 5,
   "metadata": {},
   "outputs": [
    {
     "data": {
      "text/plain": [
       "5855"
      ]
     },
     "execution_count": 5,
     "metadata": {},
     "output_type": "execute_result"
    }
   ],
   "source": [
    "#Count movies with mismatched years (wrong imdb title retrieval) or no response at all\n",
    "len(mismatch_tr)"
   ]
  },
  {
   "cell_type": "code",
   "execution_count": null,
   "metadata": {},
   "outputs": [],
   "source": [
    "#Usage of cinemagoer library\n",
    "ia=Cinemagoer()\n",
    "movie_data=ia.get_movie('0133093')"
   ]
  },
  {
   "cell_type": "code",
   "execution_count": null,
   "metadata": {},
   "outputs": [],
   "source": [
    "#Multiprocessed version for \n",
    "ret_imdb_data_parallel(5,movies.iloc[:100],retrieve_with=\"imdbid\")"
   ]
  },
  {
   "cell_type": "code",
   "execution_count": 6,
   "metadata": {},
   "outputs": [
    {
     "data": {
      "text/plain": [
       "{'assessments': {('AfroBubbleGum Test', 'fails'),\n",
       "  ('Bechdel test', 'fails'),\n",
       "  ('BubbleGum Test', 'fails'),\n",
       "  ('Celia Imrie Test', 'fails'),\n",
       "  ('Coates Test', 'fails'),\n",
       "  ('Feldman Test', 'fails'),\n",
       "  ('Landau Test', 'passes'),\n",
       "  ('Mako Mori test', 'passes'),\n",
       "  ('Raleigh Becket Test', 'fails'),\n",
       "  ('Riz Test', 'not applicable'),\n",
       "  ('Russ Test', 'fails'),\n",
       "  ('Shukla Test', 'fails'),\n",
       "  ('Tauriel Test', 'passes'),\n",
       "  ('Topside Test', 'fails'),\n",
       "  ('Tyrion Test', 'fails'),\n",
       "  ('Vito Russo test', 'fails'),\n",
       "  ('Waithe Test', 'fails'),\n",
       "  ('reverse Bechdel Test', 'passes'),\n",
       "  ('reverse Landau Test', 'passes'),\n",
       "  ('reverse Mako Mori test', 'passes'),\n",
       "  ('reverse Waithe Test', 'fails')}}"
      ]
     },
     "execution_count": 6,
     "metadata": {},
     "output_type": "execute_result"
    }
   ],
   "source": [
    "#Retrieves assesment data for a given IMDB ID\n",
    "get_assessment_data_imdb(\"tt0109424\")"
   ]
  },
  {
   "cell_type": "code",
   "execution_count": null,
   "metadata": {},
   "outputs": [],
   "source": [
    "resp=ret_wikidata_data_parallel(5,movies.iloc[:100])"
   ]
  },
  {
   "cell_type": "code",
   "execution_count": 6,
   "metadata": {},
   "outputs": [
    {
     "name": "stdout",
     "output_type": "stream",
     "text": [
      "No movie found for IMDb ID: tt1371091\n",
      "No movie found for IMDb ID: tt0256351\n",
      "No movie found for IMDb ID: tt13906516\n",
      "No movie found for IMDb ID: tt0161362\n",
      "No movie found for IMDb ID: tt0084373\n",
      "No movie found for IMDb ID: tt0904126\n",
      "No movie found for IMDb ID: tt0053410\n",
      "No movie found for IMDb ID: tt0445847\n",
      "No movie found for IMDb ID: tt0460091\n",
      "No movie found for IMDb ID: tt13667080\n",
      "No movie found for IMDb ID: tt0115193\n",
      "No movie found for IMDb ID: tt0170113\n",
      "No movie found for IMDb ID: tt0173225\n",
      "No movie found for IMDb ID: tt0079552\n",
      "No movie found for IMDb ID: Err: Kausthubham (2010)\n",
      "No movie found for IMDb ID: tt0426863\n"
     ]
    }
   ],
   "source": [
    "mdb_res=ret_moviedb_data_parallel(10,movies.iloc[:100])"
   ]
  }
 ],
 "metadata": {
  "kernelspec": {
   "display_name": "base",
   "language": "python",
   "name": "python3"
  },
  "language_info": {
   "codemirror_mode": {
    "name": "ipython",
    "version": 3
   },
   "file_extension": ".py",
   "mimetype": "text/x-python",
   "name": "python",
   "nbconvert_exporter": "python",
   "pygments_lexer": "ipython3",
   "version": "3.9.13"
  }
 },
 "nbformat": 4,
 "nbformat_minor": 2
}
